Workbook

Sheet Orders
A1: OrderID | B1: OrderDateTime | C1: Branch | D1: CustomerType | E1: PaymentType | F1: Shift | G1: DiscountPct
A2: O00001 | B2: 45852.096 | C2: Head Office Café | D2: Visitor | E2: UPI | F2: Breakfast | G2: 0.06
A3: O00002 | B3: 45862.843 | C3: Plant 2 Canteen | D3: Staff | E3: Cash | F3: Dinner | G3: 0.05
A4: O00003 | B4: 45848.661 | C4: Head Office Café | D4: Staff | E4: Card | F4: Lunch | G4: 0
A5: O00004 | B5: 45879.164 | C5: Plant 2 Canteen | D5: Visitor | E5: Cash | F5: Breakfast | G5: 0.03
A6: O00005 | B6: 45845.135 | C6: Plant 2 Canteen | D6: Visitor | E6: Card | F6: Breakfast | G6: 0.04
A7: O00006 | B7: 45863.392 | C7: Plant 1 Canteen | D7: Worker | E7: UPI | F7: Breakfast | G7: 0.1
A8: O00007 | B8: 45852.86 | C8: Plant 2 Canteen | D8: Worker | E8: Card | F8: Dinner | G8: 0.07
A9: O00008 | B9: 45863.504 | C9: Plant 1 Canteen | D9: Staff | E9: UPI | F9: Lunch | G9: 0
A10: O00009 | B10: 45844.162 | C10: Head Office Café | D10: Visitor | E10: Cash | F10: Breakfast | G10: 0.07
A11: O00010 | B11: 45862.2 | C11: Plant 1 Canteen | D11: Staff | E11: Card | F11: Breakfast | G11: 0.04
A12: O00011 | B12: 45860.003 | C12: Plant 2 Canteen | D12: Worker | E12: Cash | F12: Breakfast | G12: 0.03
A13: O00012 | B13: 45839.459 | C13: Plant 2 Canteen | D13: Staff | E13: Card | F13: Lunch | G13: 0.08
... A361: O00360 | B361: 45878.689 | C361: Plant 2 Canteen | D361: Visitor | E361: UPI | F361: Dinner | G361: 0.04

Sheet OrderLines
A1: OrderID | B1: SKU | C1: Qty | D1: UnitPrice | E1: UnitCost | F1: Category | G1: OrderDate | H1: Branch
A2: O00001 | B2: SHJ7XV | C2: 3 | D2: =VLOOKUP(B2, Menu!$A:$F, 6, 0) -> 52.45 | E2: =VLOOKUP(B2, Menu!$A:$F, 5, 0) -> 25.8 | F2: =VLOOKUP(B2, Menu!$A:$F, 3, 0) -> Snack | G2: =VLOOKUP(A2, Orders!$A:$B, 2, 0) -> 45852.096 | H2: =VLOOKUP(A2, Orders!$A:$C, 3, 0) -> Head Office Café
A3: O00002 | B3: BTIQJ7 | C3: 1 | D3: =VLOOKUP(B3, Menu!$A:$F, 6, 0) -> 30.34 | E3: =VLOOKUP(B3, Menu!$A:$F, 5, 0) -> 14.18 | F3: =VLOOKUP(B3, Menu!$A:$F, 3, 0) -> Beverage | G3: =VLOOKUP(A3, Orders!$A:$B, 2, 0) -> 45862.843 | H3: =VLOOKUP(A3, Orders!$A:$C, 3, 0) -> Plant 2 Canteen
A4: O00002 | B4: DH9SDB | C4: 1 | D4: =VLOOKUP(B4, Menu!$A:$F, 6, 0) -> 76.55 | E4: =VLOOKUP(B4, Menu!$A:$F, 5, 0) -> 38.23 | F4: =VLOOKUP(B4, Menu!$A:$F, 3, 0) -> Dessert | G4: =VLOOKUP(A4, Orders!$A:$B, 2, 0) -> 45862.843 | H4: =VLOOKUP(A4, Orders!$A:$C, 3, 0) -> Plant 2 Canteen
A5: O00003 | B5: BOC6UZ | C5: 2 | D5: =VLOOKUP(B5, Menu!$A:$F, 6, 0) -> 32.98 | E5: =VLOOKUP(B5, Menu!$A:$F, 5, 0) -> 11.84 | F5: =VLOOKUP(B5, Menu!$A:$F, 3, 0) -> Beverage | G5: =VLOOKUP(A5, Orders!$A:$B, 2, 0) -> 45848.661 | H5: =VLOOKUP(A5, Orders!$A:$C, 3, 0) -> Head Office Café
A6: O00003 | B6: SHJ7XV | C6: 1 | D6: =VLOOKUP(B6, Menu!$A:$F, 6, 0) -> 52.45 | E6: =VLOOKUP(B6, Menu!$A:$F, 5, 0) -> 25.8 | F6: =VLOOKUP(B6, Menu!$A:$F, 3, 0) -> Snack | G6: =VLOOKUP(A6, Orders!$A:$B, 2, 0) -> 45848.661 | H6: =VLOOKUP(A6, Orders!$A:$C, 3, 0) -> Head Office Café
A7: O00003 | B7: H3A3ZM | C7: 3 | D7: =VLOOKUP(B7, Menu!$A:$F, 6, 0) -> 170.83 | E7: =VLOOKUP(B7, Menu!$A:$F, 5, 0) -> 74.07 | F7: =VLOOKUP(B7, Menu!$A:$F, 3, 0) -> Hot Meal | G7: =VLOOKUP(A7, Orders!$A:$B, 2, 0) -> 45848.661 | H7: =VLOOKUP(A7, Orders!$A:$C, 3, 0) -> Head Office Café
A8: O00003 | B8: SZBIKC | C8: 1 | D8: =VLOOKUP(B8, Menu!$A:$F, 6, 0) -> 38.06 | E8: =VLOOKUP(B8, Menu!$A:$F, 5, 0) -> 19.55 | F8: =VLOOKUP(B8, Menu!$A:$F, 3, 0) -> Snack | G8: =VLOOKUP(A8, Orders!$A:$B, 2, 0) -> 45848.661 | H8: =VLOOKUP(A8, Orders!$A:$C, 3, 0) -> Head Office Café
A9: O00004 | B9: HH1DNM | C9: 2 | D9: =VLOOKUP(B9, Menu!$A:$F, 6, 0) -> 246.09 | E9: =VLOOKUP(B9, Menu!$A:$F, 5, 0) -> 112.08 | F9: =VLOOKUP(B9, Menu!$A:$F, 3, 0) -> Hot Meal | G9: =VLOOKUP(A9, Orders!$A:$B, 2, 0) -> 45879.164 | H9: =VLOOKUP(A9, Orders!$A:$C, 3, 0) -> Plant 2 Canteen
A10: O00005 | B10: SCKW5N | C10: 1 | D10: =VLOOKUP(B10, Menu!$A:$F, 6, 0) -> 70.54 | E10: =VLOOKUP(B10, Menu!$A:$F, 5, 0) -> 35.81 | F10: =VLOOKUP(B10, Menu!$A:$F, 3, 0) -> Snack | G10: =VLOOKUP(A10, Orders!$A:$B, 2, 0) -> 45845.135 | H10: =VLOOKUP(A10, Orders!$A:$C, 3, 0) -> Plant 2 Canteen
A11: O00005 | B11: B0T0PV | C11: 1 | D11: =VLOOKUP(B11, Menu!$A:$F, 6, 0) -> 28.43 | E11: =VLOOKUP(B11, Menu!$A:$F, 5, 0) -> 13.89 | F11: =VLOOKUP(B11, Menu!$A:$F, 3, 0) -> Beverage | G11: =VLOOKUP(A11, Orders!$A:$B, 2, 0) -> 45845.135 | H11: =VLOOKUP(A11, Orders!$A:$C, 3, 0) -> Plant 2 Canteen
A12: O00006 | B12: BXO6QJ | C12: 3 | D12: =VLOOKUP(B12, Menu!$A:$F, 6, 0) -> 20.11 | E12: =VLOOKUP(B12, Menu!$A:$F, 5, 0) -> 8 | F12: =VLOOKUP(B12, Menu!$A:$F, 3, 0) -> Beverage | G12: =VLOOKUP(A12, Orders!$A:$B, 2, 0) -> 45863.392 | H12: =VLOOKUP(A12, Orders!$A:$C, 3, 0) -> Plant 1 Canteen
A13: O00007 | B13: BOC6UZ | C13: 1 | D13: =VLOOKUP(B13, Menu!$A:$F, 6, 0) -> 32.98 | E13: =VLOOKUP(B13, Menu!$A:$F, 5, 0) -> 11.84 | F13: =VLOOKUP(B13, Menu!$A:$F, 3, 0) -> Beverage | G13: =VLOOKUP(A13, Orders!$A:$B, 2, 0) -> 45852.86 | H13: =VLOOKUP(A13, Orders!$A:$C, 3, 0) -> Plant 2 Canteen
... A925: O00360 | B925: BTIQJ7 | C925: 2 | D925: =VLOOKUP(B925, Menu!$A:$F, 6, 0) -> 30.34 | E925: =VLOOKUP(B925, Menu!$A:$F, 5, 0) -> 14.18 | F925: =VLOOKUP(B925, Menu!$A:$F, 3, 0) -> Beverage | G925: =VLOOKUP(A925, Orders!$A:$B, 2, 0) -> 45878.689 | H925: =VLOOKUP(A925, Orders!$A:$C, 3, 0) -> Plant 2 Canteen

Sheet Menu
A1: SKU | B1: ItemName | C1: Category | D1: SupplierID | E1: UnitCost | F1: UnitPrice
A2: HXAJI0 | B2: Veg Thali | C2: Hot Meal | D2: S009 | E2: 96.22 | F2: 227.61
A3: HDPBHS | B3: Chicken Thali | C3: Hot Meal | D3: S001 | E3: 121.24 | F3: 256.91
A4: HUZZPQ | B4: Rajma Chawal | C4: Hot Meal | D4: S005 | E4: 80.92 | F4: 146.4
A5: H3A3ZM | B5: Paneer Butter Masala + Naan | C5: Hot Meal | D5: S003 | E5: 74.07 | F5: 170.83
A6: HH1DNM | B6: Egg Curry + Rice | C6: Hot Meal | D6: S006 | E6: 112.08 | F6: 246.09
A7: SV30T9 | B7: Samosa | C7: Snack | D7: S007 | E7: 15.51 | F7: 39.95
A8: SCKW5N | B8: Veg Sandwich | C8: Snack | D8: S004 | E8: 35.81 | F8: 70.54
A9: SZBIKC | B9: Paneer Roll | C9: Snack | D9: S004 | E9: 19.55 | F9: 38.06
A10: S5NQ4F | B10: Masala Puff | C10: Snack | D10: S006 | E10: 22.61 | F10: 50.19
A11: SHJ7XV | B11: Poha | C11: Snack | D11: S003 | E11: 25.8 | F11: 52.45
A12: BTIQJ7 | B12: Tea | C12: Beverage | D12: S009 | E12: 14.18 | F12: 30.34
A13: BHL1C3 | B13: Coffee | C13: Beverage | D13: S006 | E13: 9.38 | F13: 22.2
... A20: DYTJXE | B20: Fruit Cup | C20: Dessert | D20: S007 | E20: 29.14 | F20: 57.07

Sheet Staff
A1: StaffID | B1: StaffName | C1: Role | D1: Branch | E1: HourlyRateINR
A2: E001 | B2: Tarun | C2: Cashier | D2: Plant 1 Canteen | E2: 151.58
A3: E002 | B3: Payal | C3: Cashier | D3: Head Office Café | E3: 129.61
A4: E003 | B4: Karan | C4: Cashier | D4: Head Office Café | E4: 100.98
A5: E004 | B5: Payal | C5: Cook | D5: Plant 1 Canteen | E5: 134.57
A6: E005 | B6: Vikram | C6: Cook | D6: Head Office Café | E6: 93.09
A7: E006 | B7: Rina | C7: Cashier | D7: Head Office Café | E7: 171.84
A8: E007 | B8: Sanjay | C8: Cook | D8: Plant 2 Canteen | E8: 113.29
A9: E008 | B9: Manish | C9: Cook | D9: Head Office Café | E9: 149.63
A10: E009 | B10: Pooja | C10: Server | D10: Head Office Café | E10: 118.05
A11: E010 | B11: Sourav | C11: Cashier | D11: Plant 1 Canteen | E11: 136.81
A12: E011 | B12: Neha | C12: Cashier | D12: Plant 2 Canteen | E12: 139.2
A13: E012 | B13: Amit | C13: Cook | D13: Head Office Café | E13: 106.64
... A19: E018 | B19: Payal | C19: Cashier | D19: Head Office Café | E19: 172.97

Sheet Inventory
A1: SKU | B1: OnHandQty | C1: ReorderPoint | D1: LeadTimeDays | E1: LastRestockDate
A2: HXAJI0 | B2: 198 | C2: 36 | D2: 3 | E2: 45876
A3: HDPBHS | B3: 152 | C3: 30 | D3: 6 | E3: 45861
A4: HUZZPQ | B4: 120 | C4: 25 | D4: 6 | E4: 45882
A5: H3A3ZM | B5: 130 | C5: 42 | D5: 4 | E5: 45864
A6: HH1DNM | B6: 176 | C6: 46 | D6: 3 | E6: 45871
A7: SV30T9 | B7: 81 | C7: 25 | D7: 3 | E7: 45868
A8: SCKW5N | B8: 45 | C8: 57 | D8: 4 | E8: 45840
A9: SZBIKC | B9: 89 | C9: 21 | D9: 5 | E9: 45864
A10: S5NQ4F | B10: 85 | C10: 41 | D10: 3 | E10: 45873
A11: SHJ7XV | B11: 80 | C11: 39 | D11: 2 | E11: 45861
A12: BTIQJ7 | B12: 84 | C12: 44 | D12: 4 | E12: 45845
A13: BHL1C3 | B13: 55 | C13: 34 | D13: 3 | E13: 45850
... A20: DYTJXE | B20: 53 | C20: 58 | D20: 5 | E20: 45850

Sheet Suppliers
A1: SupplierID | B1: SupplierName | C1: City | D1: Phone
A2: S001 | B2: DailyDairy 1 | C2: Howrah | D2: +91-9624636385
A3: S002 | B3: BakersHub 2 | C3: Durgapur | D3: +91-9120912992
A4: S003 | B4: FreshFoods 3 | C4: Durgapur | D4: +91-9220117054
A5: S004 | B5: Tea&Co 4 | C5: Jamshedpur | D5: +91-9489747629
A6: S005 | B6: SpiceRoute 5 | C6: Durgapur | D6: +91-9992994062
A7: S006 | B7: DailyDairy 6 | C7: Howrah | D7: +91-9966267851
A8: S007 | B8: SpiceRoute 7 | C8: Howrah | D8: +91-9430190783
A9: S008 | B9: AgroDelight 8 | C9: Kolkata | D9: +91-9357109965
A10: S009 | B10: Tea&Co 9 | C10: Howrah | D10: +91-9162196678
A11: S010 | B11: SpiceRoute 10 | C11: Jamshedpur | D11: +91-9358633898

Sheet WasteLog
A1: Date | B1: SKU | C1: Qty | D1: Reason
A2: 45867 | B2: BHL1C3 | C2: 2 | D2: Spoilage
A3: 45860 | B3: HH1DNM | C3: 4 | D3: Damaged
A4: 45853 | B4: B0T0PV | C4: 2 | D4: Expired
A5: 45879 | B5: D9T84A | C5: 2 | D5: Damaged
A6: 45891 | B6: SCKW5N | C6: 2 | D6: Spoilage
A7: 45896 | B7: HUZZPQ | C7: 1 | D7: Damaged
A8: 45890 | B8: BHL1C3 | C8: 3 | D8: Overproduction
A9: 45893 | B9: H3A3ZM | C9: 1 | D9: Overproduction
A10: 45892 | B10: DFFYVN | C10: 2 | D10: Spoilage
A11: 45894 | B11: D9T84A | C11: 1 | D11: Spoilage
A12: 45854 | B12: BTIQJ7 | C12: 1 | D12: Damaged
A13: 45850 | B13: SCKW5N | C13: 4 | D13: Damaged
... A121: 45847 | B121: SHJ7XV | C121: 2 | D121: Spoilage

Sheet Feedback
A1: Date | B1: Branch | C1: Rating | D1: Comment
A2: 45846 | B2: Plant 1 Canteen | C2: 4 | D2: Ok
A3: 45875 | B3: Head Office Café | C3: 3 | D3: Great staff
A4: 45869 | B4: Plant 2 Canteen | C4: 2 | D4: Good
A5: 45839 | B5: Plant 2 Canteen | C5: 5 | D5: Less spicy
A6: 45865 | B6: Plant 1 Canteen | C6: 3 | D6: Good
A7: 45857 | B7: Plant 2 Canteen | C7: 5 | D7: Great staff
A8: 45849 | B8: Plant 1 Canteen | C8: 2 | D8: Less spicy
A9: 45892 | B9: Plant 1 Canteen | C9: 4 | D9: Great staff
A10: 45840 | B10: Plant 2 Canteen | C10: 5 | D10: Great staff
A11: 45847 | B11: Head Office Café | C11: 3 | D11: Ok
A12: 45875 | B12: Plant 1 Canteen | C12: 3 | D12: Loved chai
A13: 45868 | B13: Plant 2 Canteen | C13: 5 | D13: Ok
... A17: 45896 | B17: Head Office Café | C17: 3 | D17: Crowded
A18: 45849 | B18: Plant 1 Canteen | C18: 4
A19: 45877 | B19: Plant 2 Canteen | C19: 5 | D19: Less spicy
A20: 45881 | B20: Plant 2 Canteen | C20: 5 | D20: Ok
A21: 45868 | B21: Plant 2 Canteen | C21: 3 | D21: Crowded
A22: 45869 | B22: Plant 1 Canteen | C22: 5 | D22: Less spicy
A23: 45867 | B23: Head Office Café | C23: 5 | D23: Slow service
A24: 45870 | B24: Plant 2 Canteen | C24: 4 | D24: Great staff
A25: 45874 | B25: Plant 1 Canteen | C25: 3 | D25: Ok
A26: 45892 | B26: Plant 1 Canteen | C26: 5 | D26: Slow service
A27: 45881 | B27: Plant 2 Canteen | C27: 2 | D27: Great staff
A28: 45887 | B28: Plant 1 Canteen | C28: 4 | D28: Slow service
A29: 45863 | B29: Head Office Café | C29: 3 | D29: Great staff
A30: 45875 | B30: Plant 1 Canteen | C30: 5 | D30: Crowded
A31: 45895 | B31: Plant 2 Canteen | C31: 5
A32: 45873 | B32: Head Office Café | C32: 2 | D32: Good
A33: 45863 | B33: Head Office Café | C33: 4 | D33: Ok
A34: 45843 | B34: Head Office Café | C34: 5 | D34: Less spicy
A35: 45880 | B35: Plant 1 Canteen | C35: 2 | D35: Good
A36: 45864 | B36: Plant 1 Canteen | C36: 3 | D36: Crowded
A37: 45875 | B37: Plant 2 Canteen | C37: 5 | D37: Ok
A38: 45872 | B38: Plant 1 Canteen | C38: 5 | D38: Good
A39: 45867 | B39: Plant 2 Canteen | C39: 2 | D39: Good
A40: 45852 | B40: Plant 2 Canteen | C40: 4 | D40: Less spicy
A41: 45883 | B41: Plant 1 Canteen | C41: 5 | D41: Less spicy
A42: 45885 | B42: Plant 1 Canteen | C42: 5 | D42: Crowded
A43: 45869 | B43: Plant 1 Canteen | C43: 4
...
