Workbook

Sheet Orders
A1: OrderID | B1: OrderDateTime | C1: Branch | D1: CustomerType | E1: PaymentType | F1: Shift | G1: DiscountPct | H1: HasBeverageLine | I1: OrderTotalRevenue | J1: ComboFlag | K1: DiscountFlag
A2: O00001 | B2: 45852.096 | C2: Head Office Café | D2: Visitor | E2: UPI | F2: Breakfast | G2: 0.06 | H2: =(COUNTIFS(OrderLines!$A:$A,A2,OrderLines!$F:$F,"Beverage")>0) -> FALSE | I2: =SUMIFS(OrderLines!$I:$I,OrderLines!$A:$A,A2) -> 147.909 | J2: =IF(AND(COUNTIFS(OrderLines!$A$2:$A$925,A2,OrderLines!$F$2:$F$925,"Hot Meal")>0,COUNTIFS(OrderLines!$A$2:$A$925,A2,OrderLines!$F$2:$F$925,"Beverage")>0),"Combo","Single") -> Single | K2: =IF(SUMPRODUCT((OrderLines!$A$2:$A$925=A2)*OrderLines!$C$2:$C$925*OrderLines!$D$2:$D$925)*G2>40,"HighDisc","OK") -> OK
A3: O00002 | B3: 45862.843 | C3: Plant 2 Canteen | D3: Staff | E3: Cash | F3: Dinner | G3: 0.05 | H3: =(COUNTIFS(OrderLines!$A:$A,A3,OrderLines!$F:$F,"Beverage")>0) -> TRUE | I3: =SUMIFS(OrderLines!$I:$I,OrderLines!$A:$A,A3) -> 101.5455 | J3: =IF(AND(COUNTIFS(OrderLines!$A$2:$A$925,A3,OrderLines!$F$2:$F$925,"Hot Meal")>0,COUNTIFS(OrderLines!$A$2:$A$925,A3,OrderLines!$F$2:$F$925,"Beverage")>0),"Combo","Single") -> Single | K3: =IF(SUMPRODUCT((OrderLines!$A$2:$A$925=A3)*OrderLines!$C$2:$C$925*OrderLines!$D$2:$D$925)*G3>40,"HighDisc","OK") -> OK
A4: O00003 | B4: 45848.661 | C4: Head Office Café | D4: Staff | E4: Card | F4: Lunch | G4: 0 | H4: =(COUNTIFS(OrderLines!$A:$A,A4,OrderLines!$F:$F,"Beverage")>0) -> TRUE | I4: =SUMIFS(OrderLines!$I:$I,OrderLines!$A:$A,A4) -> 668.96 | J4: =IF(AND(COUNTIFS(OrderLines!$A$2:$A$925,A4,OrderLines!$F$2:$F$925,"Hot Meal")>0,COUNTIFS(OrderLines!$A$2:$A$925,A4,OrderLines!$F$2:$F$925,"Beverage")>0),"Combo","Single") -> Combo | K4: =IF(SUMPRODUCT((OrderLines!$A$2:$A$925=A4)*OrderLines!$C$2:$C$925*OrderLines!$D$2:$D$925)*G4>40,"HighDisc","OK") -> OK
A5: O00004 | B5: 45879.164 | C5: Plant 2 Canteen | D5: Visitor | E5: Cash | F5: Breakfast | G5: 0.03 | H5: =(COUNTIFS(OrderLines!$A:$A,A5,OrderLines!$F:$F,"Beverage")>0) -> FALSE | I5: =SUMIFS(OrderLines!$I:$I,OrderLines!$A:$A,A5) -> 477.4146 | J5: =IF(AND(COUNTIFS(OrderLines!$A$2:$A$925,A5,OrderLines!$F$2:$F$925,"Hot Meal")>0,COUNTIFS(OrderLines!$A$2:$A$925,A5,OrderLines!$F$2:$F$925,"Beverage")>0),"Combo","Single") -> Single | K5: =IF(SUMPRODUCT((OrderLines!$A$2:$A$925=A5)*OrderLines!$C$2:$C$925*OrderLines!$D$2:$D$925)*G5>40,"HighDisc","OK") -> OK
A6: O00005 | B6: 45845.135 | C6: Plant 2 Canteen | D6: Visitor | E6: Card | F6: Breakfast | G6: 0.04 | H6: =(COUNTIFS(OrderLines!$A:$A,A6,OrderLines!$F:$F,"Beverage")>0) -> TRUE | I6: =SUMIFS(OrderLines!$I:$I,OrderLines!$A:$A,A6) -> 95.0112 | J6: =IF(AND(COUNTIFS(OrderLines!$A$2:$A$925,A6,OrderLines!$F$2:$F$925,"Hot Meal")>0,COUNTIFS(OrderLines!$A$2:$A$925,A6,OrderLines!$F$2:$F$925,"Beverage")>0),"Combo","Single") -> Single | K6: =IF(SUMPRODUCT((OrderLines!$A$2:$A$925=A6)*OrderLines!$C$2:$C$925*OrderLines!$D$2:$D$925)*G6>40,"HighDisc","OK") -> OK
A7: O00006 | B7: 45863.392 | C7: Plant 1 Canteen | D7: Worker | E7: UPI | F7: Breakfast | G7: 0.1 | H7: =(COUNTIFS(OrderLines!$A:$A,A7,OrderLines!$F:$F,"Beverage")>0) -> TRUE | I7: =SUMIFS(OrderLines!$I:$I,OrderLines!$A:$A,A7) -> 54.297 | J7: =IF(AND(COUNTIFS(OrderLines!$A$2:$A$925,A7,OrderLines!$F$2:$F$925,"Hot Meal")>0,COUNTIFS(OrderLines!$A$2:$A$925,A7,OrderLines!$F$2:$F$925,"Beverage")>0),"Combo","Single") -> Single | K7: =IF(SUMPRODUCT((OrderLines!$A$2:$A$925=A7)*OrderLines!$C$2:$C$925*OrderLines!$D$2:$D$925)*G7>40,"HighDisc","OK") -> OK
A8: O00007 | B8: 45852.86 | C8: Plant 2 Canteen | D8: Worker | E8: Card | F8: Dinner | G8: 0.07 | H8: =(COUNTIFS(OrderLines!$A:$A,A8,OrderLines!$F:$F,"Beverage")>0) -> TRUE | I8: =SUMIFS(OrderLines!$I:$I,OrderLines!$A:$A,A8) -> 348.4152 | J8: =IF(AND(COUNTIFS(OrderLines!$A$2:$A$925,A8,OrderLines!$F$2:$F$925,"Hot Meal")>0,COUNTIFS(OrderLines!$A$2:$A$925,A8,OrderLines!$F$2:$F$925,"Beverage")>0),"Combo","Single") -> Combo | K8: =IF(SUMPRODUCT((OrderLines!$A$2:$A$925=A8)*OrderLines!$C$2:$C$925*OrderLines!$D$2:$D$925)*G8>40,"HighDisc","OK") -> OK
A9: O00008 | B9: 45863.504 | C9: Plant 1 Canteen | D9: Staff | E9: UPI | F9: Lunch | G9: 0 | H9: =(COUNTIFS(OrderLines!$A:$A,A9,OrderLines!$F:$F,"Beverage")>0) -> TRUE | I9: =SUMIFS(OrderLines!$I:$I,OrderLines!$A:$A,A9) -> 223.75 | J9: =IF(AND(COUNTIFS(OrderLines!$A$2:$A$925,A9,OrderLines!$F$2:$F$925,"Hot Meal")>0,COUNTIFS(OrderLines!$A$2:$A$925,A9,OrderLines!$F$2:$F$925,"Beverage")>0),"Combo","Single") -> Single | K9: =IF(SUMPRODUCT((OrderLines!$A$2:$A$925=A9)*OrderLines!$C$2:$C$925*OrderLines!$D$2:$D$925)*G9>40,"HighDisc","OK") -> OK
A10: O00009 | B10: 45844.162 | C10: Head Office Café | D10: Visitor | E10: Cash | F10: Breakfast | G10: 0.07 | H10: =(COUNTIFS(OrderLines!$A:$A,A10,OrderLines!$F:$F,"Beverage")>0) -> FALSE | I10: =SUMIFS(OrderLines!$I:$I,OrderLines!$A:$A,A10) -> 459.2898 | J10: =IF(AND(COUNTIFS(OrderLines!$A$2:$A$925,A10,OrderLines!$F$2:$F$925,"Hot Meal")>0,COUNTIFS(OrderLines!$A$2:$A$925,A10,OrderLines!$F$2:$F$925,"Beverage")>0),"Combo","Single") -> Single | K10: =IF(SUMPRODUCT((OrderLines!$A$2:$A$925=A10)*OrderLines!$C$2:$C$925*OrderLines!$D$2:$D$925)*G10>40,"HighDisc","OK") -> OK
A11: O00010 | B11: 45862.2 | C11: Plant 1 Canteen | D11: Staff | E11: Card | F11: Breakfast | G11: 0.04 | H11: =(COUNTIFS(OrderLines!$A:$A,A11,OrderLines!$F:$F,"Beverage")>0) -> TRUE | I11: =SUMIFS(OrderLines!$I:$I,OrderLines!$A:$A,A11) -> 420.0768 | J11: =IF(AND(COUNTIFS(OrderLines!$A$2:$A$925,A11,OrderLines!$F$2:$F$925,"Hot Meal")>0,COUNTIFS(OrderLines!$A$2:$A$925,A11,OrderLines!$F$2:$F$925,"Beverage")>0),"Combo","Single") -> Combo | K11: =IF(SUMPRODUCT((OrderLines!$A$2:$A$925=A11)*OrderLines!$C$2:$C$925*OrderLines!$D$2:$D$925)*G11>40,"HighDisc","OK") -> OK
A12: O00011 | B12: 45860.003 | C12: Plant 2 Canteen | D12: Worker | E12: Cash | F12: Breakfast | G12: 0.03 | H12: =(COUNTIFS(OrderLines!$A:$A,A12,OrderLines!$F:$F,"Beverage")>0) -> TRUE | I12: =SUMIFS(OrderLines!$I:$I,OrderLines!$A:$A,A12) -> 27.5771 | J12: =IF(AND(COUNTIFS(OrderLines!$A$2:$A$925,A12,OrderLines!$F$2:$F$925,"Hot Meal")>0,COUNTIFS(OrderLines!$A$2:$A$925,A12,OrderLines!$F$2:$F$925,"Beverage")>0),"Combo","Single") -> Single | K12: =IF(SUMPRODUCT((OrderLines!$A$2:$A$925=A12)*OrderLines!$C$2:$C$925*OrderLines!$D$2:$D$925)*G12>40,"HighDisc","OK") -> OK
A13: O00012 | B13: 45839.459 | C13: Plant 2 Canteen | D13: Staff | E13: Card | F13: Lunch | G13: 0.08 | H13: =(COUNTIFS(OrderLines!$A:$A,A13,OrderLines!$F:$F,"Beverage")>0) -> FALSE | I13: =SUMIFS(OrderLines!$I:$I,OrderLines!$A:$A,A13) -> 98.118 | J13: =IF(AND(COUNTIFS(OrderLines!$A$2:$A$925,A13,OrderLines!$F$2:$F$925,"Hot Meal")>0,COUNTIFS(OrderLines!$A$2:$A$925,A13,OrderLines!$F$2:$F$925,"Beverage")>0),"Combo","Single") -> Single | K13: =IF(SUMPRODUCT((OrderLines!$A$2:$A$925=A13)*OrderLines!$C$2:$C$925*OrderLines!$D$2:$D$925)*G13>40,"HighDisc","OK") -> OK
... A361: O00360 | B361: 45878.689 | C361: Plant 2 Canteen | D361: Visitor | E361: UPI | F361: Dinner | G361: 0.04 | H361: =(COUNTIFS(OrderLines!$A:$A,A361,OrderLines!$F:$F,"Beverage")>0) -> TRUE | I361: =SUMIFS(OrderLines!$I:$I,OrderLines!$A:$A,A361) -> 962.1504 | J361: =IF(AND(COUNTIFS(OrderLines!$A$2:$A$925,A361,OrderLines!$F$2:$F$925,"Hot Meal")>0,COUNTIFS(OrderLines!$A$2:$A$925,A361,OrderLines!$F$2:$F$925,"Beverage")>0),"Combo","Single") -> Combo | K361: =IF(SUMPRODUCT((OrderLines!$A$2:$A$925=A361)*OrderLines!$C$2:$C$925*OrderLines!$D$2:$D$925)*G361>40,"HighDisc","OK") -> HighDisc

Sheet OrderLines
A1: OrderID | B1: SKU | C1: Qty | D1: UnitPrice | E1: UnitCost | F1: Category | G1: OrderDate | H1: Branch | I1: LineNetAmount | J1: Shift | K1: PaymentType | L1: LineCost
A2: O00001 | B2: SHJ7XV | C2: 3 | D2: =VLOOKUP(B2, Menu!$A:$F, 6, 0) -> 52.45 | E2: =VLOOKUP(B2, Menu!$A:$F, 5, 0) -> 25.8 | F2: =VLOOKUP(B2, Menu!$A:$F, 3, 0) -> Snack | G2: =VLOOKUP(A2, Orders!$A:$B, 2, 0) -> 45852.096 | H2: =VLOOKUP(A2, Orders!$A:$C, 3, 0) -> Head Office Café | I2: =C2*D2*(1-VLOOKUP(A2,Orders!$A:$G,7,0)) -> 147.909 | J2: =VLOOKUP(A2,Orders!$A:$G,6,0) -> Breakfast | K2: =VLOOKUP(A2,Orders!$A:$G,5,0) -> UPI | L2: =C2*E2 -> 77.4
A3: O00002 | B3: BTIQJ7 | C3: 1 | D3: =VLOOKUP(B3, Menu!$A:$F, 6, 0) -> 30.34 | E3: =VLOOKUP(B3, Menu!$A:$F, 5, 0) -> 14.18 | F3: =VLOOKUP(B3, Menu!$A:$F, 3, 0) -> Beverage | G3: =VLOOKUP(A3, Orders!$A:$B, 2, 0) -> 45862.843 | H3: =VLOOKUP(A3, Orders!$A:$C, 3, 0) -> Plant 2 Canteen | I3: =C3*D3*(1-VLOOKUP(A3,Orders!$A:$G,7,0)) -> 28.823 | J3: =VLOOKUP(A3,Orders!$A:$G,6,0) -> Dinner | K3: =VLOOKUP(A3,Orders!$A:$G,5,0) -> Cash | L3: =C3*E3 -> 14.18
A4: O00002 | B4: DH9SDB | C4: 1 | D4: =VLOOKUP(B4, Menu!$A:$F, 6, 0) -> 76.55 | E4: =VLOOKUP(B4, Menu!$A:$F, 5, 0) -> 38.23 | F4: =VLOOKUP(B4, Menu!$A:$F, 3, 0) -> Dessert | G4: =VLOOKUP(A4, Orders!$A:$B, 2, 0) -> 45862.843 | H4: =VLOOKUP(A4, Orders!$A:$C, 3, 0) -> Plant 2 Canteen | I4: =C4*D4*(1-VLOOKUP(A4,Orders!$A:$G,7,0)) -> 72.7225 | J4: =VLOOKUP(A4,Orders!$A:$G,6,0) -> Dinner | K4: =VLOOKUP(A4,Orders!$A:$G,5,0) -> Cash | L4: =C4*E4 -> 38.23
A5: O00003 | B5: BOC6UZ | C5: 2 | D5: =VLOOKUP(B5, Menu!$A:$F, 6, 0) -> 32.98 | E5: =VLOOKUP(B5, Menu!$A:$F, 5, 0) -> 11.84 | F5: =VLOOKUP(B5, Menu!$A:$F, 3, 0) -> Beverage | G5: =VLOOKUP(A5, Orders!$A:$B, 2, 0) -> 45848.661 | H5: =VLOOKUP(A5, Orders!$A:$C, 3, 0) -> Head Office Café | I5: =C5*D5*(1-VLOOKUP(A5,Orders!$A:$G,7,0)) -> 65.96 | J5: =VLOOKUP(A5,Orders!$A:$G,6,0) -> Lunch | K5: =VLOOKUP(A5,Orders!$A:$G,5,0) -> Card | L5: =C5*E5 -> 23.68
A6: O00003 | B6: SHJ7XV | C6: 1 | D6: =VLOOKUP(B6, Menu!$A:$F, 6, 0) -> 52.45 | E6: =VLOOKUP(B6, Menu!$A:$F, 5, 0) -> 25.8 | F6: =VLOOKUP(B6, Menu!$A:$F, 3, 0) -> Snack | G6: =VLOOKUP(A6, Orders!$A:$B, 2, 0) -> 45848.661 | H6: =VLOOKUP(A6, Orders!$A:$C, 3, 0) -> Head Office Café | I6: =C6*D6*(1-VLOOKUP(A6,Orders!$A:$G,7,0)) -> 52.45 | J6: =VLOOKUP(A6,Orders!$A:$G,6,0) -> Lunch | K6: =VLOOKUP(A6,Orders!$A:$G,5,0) -> Card | L6: =C6*E6 -> 25.8
A7: O00003 | B7: H3A3ZM | C7: 3 | D7: =VLOOKUP(B7, Menu!$A:$F, 6, 0) -> 170.83 | E7: =VLOOKUP(B7, Menu!$A:$F, 5, 0) -> 74.07 | F7: =VLOOKUP(B7, Menu!$A:$F, 3, 0) -> Hot Meal | G7: =VLOOKUP(A7, Orders!$A:$B, 2, 0) -> 45848.661 | H7: =VLOOKUP(A7, Orders!$A:$C, 3, 0) -> Head Office Café | I7: =C7*D7*(1-VLOOKUP(A7,Orders!$A:$G,7,0)) -> 512.49 | J7: =VLOOKUP(A7,Orders!$A:$G,6,0) -> Lunch | K7: =VLOOKUP(A7,Orders!$A:$G,5,0) -> Card | L7: =C7*E7 -> 222.21
A8: O00003 | B8: SZBIKC | C8: 1 | D8: =VLOOKUP(B8, Menu!$A:$F, 6, 0) -> 38.06 | E8: =VLOOKUP(B8, Menu!$A:$F, 5, 0) -> 19.55 | F8: =VLOOKUP(B8, Menu!$A:$F, 3, 0) -> Snack | G8: =VLOOKUP(A8, Orders!$A:$B, 2, 0) -> 45848.661 | H8: =VLOOKUP(A8, Orders!$A:$C, 3, 0) -> Head Office Café | I8: =C8*D8*(1-VLOOKUP(A8,Orders!$A:$G,7,0)) -> 38.06 | J8: =VLOOKUP(A8,Orders!$A:$G,6,0) -> Lunch | K8: =VLOOKUP(A8,Orders!$A:$G,5,0) -> Card | L8: =C8*E8 -> 19.55
A9: O00004 | B9: HH1DNM | C9: 2 | D9: =VLOOKUP(B9, Menu!$A:$F, 6, 0) -> 246.09 | E9: =VLOOKUP(B9, Menu!$A:$F, 5, 0) -> 112.08 | F9: =VLOOKUP(B9, Menu!$A:$F, 3, 0) -> Hot Meal | G9: =VLOOKUP(A9, Orders!$A:$B, 2, 0) -> 45879.164 | H9: =VLOOKUP(A9, Orders!$A:$C, 3, 0) -> Plant 2 Canteen | I9: =C9*D9*(1-VLOOKUP(A9,Orders!$A:$G,7,0)) -> 477.4146 | J9: =VLOOKUP(A9,Orders!$A:$G,6,0) -> Breakfast | K9: =VLOOKUP(A9,Orders!$A:$G,5,0) -> Cash | L9: =C9*E9 -> 224.16
A10: O00005 | B10: SCKW5N | C10: 1 | D10: =VLOOKUP(B10, Menu!$A:$F, 6, 0) -> 70.54 | E10: =VLOOKUP(B10, Menu!$A:$F, 5, 0) -> 35.81 | F10: =VLOOKUP(B10, Menu!$A:$F, 3, 0) -> Snack | G10: =VLOOKUP(A10, Orders!$A:$B, 2, 0) -> 45845.135 | H10: =VLOOKUP(A10, Orders!$A:$C, 3, 0) -> Plant 2 Canteen | I10: =C10*D10*(1-VLOOKUP(A10,Orders!$A:$G,7,0)) -> 67.7184 | J10: =VLOOKUP(A10,Orders!$A:$G,6,0) -> Breakfast | K10: =VLOOKUP(A10,Orders!$A:$G,5,0) -> Card | L10: =C10*E10 -> 35.81
A11: O00005 | B11: B0T0PV | C11: 1 | D11: =VLOOKUP(B11, Menu!$A:$F, 6, 0) -> 28.43 | E11: =VLOOKUP(B11, Menu!$A:$F, 5, 0) -> 13.89 | F11: =VLOOKUP(B11, Menu!$A:$F, 3, 0) -> Beverage | G11: =VLOOKUP(A11, Orders!$A:$B, 2, 0) -> 45845.135 | H11: =VLOOKUP(A11, Orders!$A:$C, 3, 0) -> Plant 2 Canteen | I11: =C11*D11*(1-VLOOKUP(A11,Orders!$A:$G,7,0)) -> 27.2928 | J11: =VLOOKUP(A11,Orders!$A:$G,6,0) -> Breakfast | K11: =VLOOKUP(A11,Orders!$A:$G,5,0) -> Card | L11: =C11*E11 -> 13.89
A12: O00006 | B12: BXO6QJ | C12: 3 | D12: =VLOOKUP(B12, Menu!$A:$F, 6, 0) -> 20.11 | E12: =VLOOKUP(B12, Menu!$A:$F, 5, 0) -> 8 | F12: =VLOOKUP(B12, Menu!$A:$F, 3, 0) -> Beverage | G12: =VLOOKUP(A12, Orders!$A:$B, 2, 0) -> 45863.392 | H12: =VLOOKUP(A12, Orders!$A:$C, 3, 0) -> Plant 1 Canteen | I12: =C12*D12*(1-VLOOKUP(A12,Orders!$A:$G,7,0)) -> 54.297 | J12: =VLOOKUP(A12,Orders!$A:$G,6,0) -> Breakfast | K12: =VLOOKUP(A12,Orders!$A:$G,5,0) -> UPI | L12: =C12*E12 -> 24
A13: O00007 | B13: BOC6UZ | C13: 1 | D13: =VLOOKUP(B13, Menu!$A:$F, 6, 0) -> 32.98 | E13: =VLOOKUP(B13, Menu!$A:$F, 5, 0) -> 11.84 | F13: =VLOOKUP(B13, Menu!$A:$F, 3, 0) -> Beverage | G13: =VLOOKUP(A13, Orders!$A:$B, 2, 0) -> 45852.86 | H13: =VLOOKUP(A13, Orders!$A:$C, 3, 0) -> Plant 2 Canteen | I13: =C13*D13*(1-VLOOKUP(A13,Orders!$A:$G,7,0)) -> 30.6714 | J13: =VLOOKUP(A13,Orders!$A:$G,6,0) -> Dinner | K13: =VLOOKUP(A13,Orders!$A:$G,5,0) -> Card | L13: =C13*E13 -> 11.84
... A925: O00360 | B925: BTIQJ7 | C925: 2 | D925: =VLOOKUP(B925, Menu!$A:$F, 6, 0) -> 30.34 | E925: =VLOOKUP(B925, Menu!$A:$F, 5, 0) -> 14.18 | F925: =VLOOKUP(B925, Menu!$A:$F, 3, 0) -> Beverage | G925: =VLOOKUP(A925, Orders!$A:$B, 2, 0) -> 45878.689 | H925: =VLOOKUP(A925, Orders!$A:$C, 3, 0) -> Plant 2 Canteen | I925: =C925*D925*(1-VLOOKUP(A925,Orders!$A:$G,7,0)) -> 58.2528 | J925: =VLOOKUP(A925,Orders!$A:$G,6,0) -> Dinner | K925: =VLOOKUP(A925,Orders!$A:$G,5,0) -> UPI | L925: =C925*E925 -> 28.36

Sheet OrdersCalc
A1: OrderID | B1: Branch | C1: Shift | D1: ComboFlag | E1: OrderTotalRevenue | F1: OrderTotalCost | G1: GrossProfit | H1: GrossMarginPct | I1: ComboKey | K1: ComboKey | L1: Count (filtered) | M1: Rank
A2: =Orders!A2 -> O00001 | B2: =Orders!C2 -> Head Office Café | C2: =Orders!F2 -> Breakfast | D2: =Orders!J2 -> Single | E2: =Orders!I2 -> 147.909 | F2: =SUMIF(OrderLines!$A$2:$A$925,A2,OrderLines!$L$2:$L$925) -> 77.4 | G2: =E2-F2 -> 70.509 | H2: =IFERROR(G2/E2,0) -> 0.47670527 | I2: =_xlfn.TEXTJOIN(" + ",TRUE,IF(COUNTIFS(OrderLines!$A$2:$A$925,A2,OrderLines!$F$2:$F$925,"Beverage")>0,"Beverage",""),IF(COUNTIFS(OrderLines!$A$2:$A$925,A2,OrderLines!$F$2:$F$925,"Dessert")>0,"Dessert",""),IF(COUNTIFS(OrderLines!$A$2:$A$925,A2,OrderLines!$F$2:$F$925,"Hot Meal")>0,"Hot Meal",""),IF(COUNTIFS(OrderLines!$A$2:$A$925,A2,OrderLines!$F$2:$F$925,"Snack")>0,"Snack","")) -> Snack | K2: Beverage | L2: =COUNTIFS($I$2:$I$361,K2,$B$2:$B$361,IF('Dashboard '!$B$4="All","*",'Dashboard '!$B$4),$C$2:$C$361,IF('Dashboard '!$E$4="All","*",'Dashboard '!$E$4)) -> 34 | M2: =RANK(L2,$L$2:$L$16)+COUNTIF($L$2:L2,L2)-1 -> 1
A3: =Orders!A3 -> O00002 | B3: =Orders!C3 -> Plant 2 Canteen | C3: =Orders!F3 -> Dinner | D3: =Orders!J3 -> Single | E3: =Orders!I3 -> 101.5455 | F3: =SUMIF(OrderLines!$A$2:$A$925,A3,OrderLines!$L$2:$L$925) -> 52.41 | G3: =E3-F3 -> 49.1355 | H3: =IFERROR(G3/E3,0) -> 0.48387669 | I3: =_xlfn.TEXTJOIN(" + ",TRUE,IF(COUNTIFS(OrderLines!$A$2:$A$925,A3,OrderLines!$F$2:$F$925,"Beverage")>0,"Beverage",""),IF(COUNTIFS(OrderLines!$A$2:$A$925,A3,OrderLines!$F$2:$F$925,"Dessert")>0,"Dessert",""),IF(COUNTIFS(OrderLines!$A$2:$A$925,A3,OrderLines!$F$2:$F$925,"Hot Meal")>0,"Hot Meal",""),IF(COUNTIFS(OrderLines!$A$2:$A$925,A3,OrderLines!$F$2:$F$925,"Snack")>0,"Snack","")) -> Beverage + Dessert | K3: Dessert | L3: =COUNTIFS($I$2:$I$361,K3,$B$2:$B$361,IF('Dashboard '!$B$4="All","*",'Dashboard '!$B$4),$C$2:$C$361,IF('Dashboard '!$E$4="All","*",'Dashboard '!$E$4)) -> 12 | M3: =RANK(L3,$L$2:$L$16)+COUNTIF($L$2:L3,L3)-1 -> 14
A4: =Orders!A4 -> O00003 | B4: =Orders!C4 -> Head Office Café | C4: =Orders!F4 -> Lunch | D4: =Orders!J4 -> Combo | E4: =Orders!I4 -> 668.96 | F4: =SUMIF(OrderLines!$A$2:$A$925,A4,OrderLines!$L$2:$L$925) -> 291.24 | G4: =E4-F4 -> 377.72 | H4: =IFERROR(G4/E4,0) -> 0.56463765 | I4: =_xlfn.TEXTJOIN(" + ",TRUE,IF(COUNTIFS(OrderLines!$A$2:$A$925,A4,OrderLines!$F$2:$F$925,"Beverage")>0,"Beverage",""),IF(COUNTIFS(OrderLines!$A$2:$A$925,A4,OrderLines!$F$2:$F$925,"Dessert")>0,"Dessert",""),IF(COUNTIFS(OrderLines!$A$2:$A$925,A4,OrderLines!$F$2:$F$925,"Hot Meal")>0,"Hot Meal",""),IF(COUNTIFS(OrderLines!$A$2:$A$925,A4,OrderLines!$F$2:$F$925,"Snack")>0,"Snack","")) -> Beverage + Hot Meal + Snack | K4: Hot Meal | L4: =COUNTIFS($I$2:$I$361,K4,$B$2:$B$361,IF('Dashboard '!$B$4="All","*",'Dashboard '!$B$4),$C$2:$C$361,IF('Dashboard '!$E$4="All","*",'Dashboard '!$E$4)) -> 27 | M4: =RANK(L4,$L$2:$L$16)+COUNTIF($L$2:L4,L4)-1 -> 5
A5: =Orders!A5 -> O00004 | B5: =Orders!C5 -> Plant 2 Canteen | C5: =Orders!F5 -> Breakfast | D5: =Orders!J5 -> Single | E5: =Orders!I5 -> 477.4146 | F5: =SUMIF(OrderLines!$A$2:$A$925,A5,OrderLines!$L$2:$L$925) -> 224.16 | G5: =E5-F5 -> 253.2546 | H5: =IFERROR(G5/E5,0) -> 0.530471 | I5: =_xlfn.TEXTJOIN(" + ",TRUE,IF(COUNTIFS(OrderLines!$A$2:$A$925,A5,OrderLines!$F$2:$F$925,"Beverage")>0,"Beverage",""),IF(COUNTIFS(OrderLines!$A$2:$A$925,A5,OrderLines!$F$2:$F$925,"Dessert")>0,"Dessert",""),IF(COUNTIFS(OrderLines!$A$2:$A$925,A5,OrderLines!$F$2:$F$925,"Hot Meal")>0,"Hot Meal",""),IF(COUNTIFS(OrderLines!$A$2:$A$925,A5,OrderLines!$F$2:$F$925,"Snack")>0,"Snack","")) -> Hot Meal | K5: Snack | L5: =COUNTIFS($I$2:$I$361,K5,$B$2:$B$361,IF('Dashboard '!$B$4="All","*",'Dashboard '!$B$4),$C$2:$C$361,IF('Dashboard '!$E$4="All","*",'Dashboard '!$E$4)) -> 29 | M5: =RANK(L5,$L$2:$L$16)+COUNTIF($L$2:L5,L5)-1 -> 3
A6: =Orders!A6 -> O00005 | B6: =Orders!C6 -> Plant 2 Canteen | C6: =Orders!F6 -> Breakfast | D6: =Orders!J6 -> Single | E6: =Orders!I6 -> 95.0112 | F6: =SUMIF(OrderLines!$A$2:$A$925,A6,OrderLines!$L$2:$L$925) -> 49.7 | G6: =E6-F6 -> 45.3112 | H6: =IFERROR(G6/E6,0) -> 0.47690378 | I6: =_xlfn.TEXTJOIN(" + ",TRUE,IF(COUNTIFS(OrderLines!$A$2:$A$925,A6,OrderLines!$F$2:$F$925,"Beverage")>0,"Beverage",""),IF(COUNTIFS(OrderLines!$A$2:$A$925,A6,OrderLines!$F$2:$F$925,"Dessert")>0,"Dessert",""),IF(COUNTIFS(OrderLines!$A$2:$A$925,A6,OrderLines!$F$2:$F$925,"Hot Meal")>0,"Hot Meal",""),IF(COUNTIFS(OrderLines!$A$2:$A$925,A6,OrderLines!$F$2:$F$925,"Snack")>0,"Snack","")) -> Beverage + Snack | K6: Beverage + Dessert | L6: =COUNTIFS($I$2:$I$361,K6,$B$2:$B$361,IF('Dashboard '!$B$4="All","*",'Dashboard '!$B$4),$C$2:$C$361,IF('Dashboard '!$E$4="All","*",'Dashboard '!$E$4)) -> 23 | M6: =RANK(L6,$L$2:$L$16)+COUNTIF($L$2:L6,L6)-1 -> 10
A7: =Orders!A7 -> O00006 | B7: =Orders!C7 -> Plant 1 Canteen | C7: =Orders!F7 -> Breakfast | D7: =Orders!J7 -> Single | E7: =Orders!I7 -> 54.297 | F7: =SUMIF(OrderLines!$A$2:$A$925,A7,OrderLines!$L$2:$L$925) -> 24 | G7: =E7-F7 -> 30.297 | H7: =IFERROR(G7/E7,0) -> 0.55798663 | I7: =_xlfn.TEXTJOIN(" + ",TRUE,IF(COUNTIFS(OrderLines!$A$2:$A$925,A7,OrderLines!$F$2:$F$925,"Beverage")>0,"Beverage",""),IF(COUNTIFS(OrderLines!$A$2:$A$925,A7,OrderLines!$F$2:$F$925,"Dessert")>0,"Dessert",""),IF(COUNTIFS(OrderLines!$A$2:$A$925,A7,OrderLines!$F$2:$F$925,"Hot Meal")>0,"Hot Meal",""),IF(COUNTIFS(OrderLines!$A$2:$A$925,A7,OrderLines!$F$2:$F$925,"Snack")>0,"Snack","")) -> Beverage | K7: Beverage + Hot Meal | L7: =COUNTIFS($I$2:$I$361,K7,$B$2:$B$361,IF('Dashboard '!$B$4="All","*",'Dashboard '!$B$4),$C$2:$C$361,IF('Dashboard '!$E$4="All","*",'Dashboard '!$E$4)) -> 25 | M7: =RANK(L7,$L$2:$L$16)+COUNTIF($L$2:L7,L7)-1 -> 8
A8: =Orders!A8 -> O00007 | B8: =Orders!C8 -> Plant 2 Canteen | C8: =Orders!F8 -> Dinner | D8: =Orders!J8 -> Combo | E8: =Orders!I8 -> 348.4152 | F8: =SUMIF(OrderLines!$A$2:$A$925,A8,OrderLines!$L$2:$L$925) -> 159.98 | G8: =E8-F8 -> 188.4352 | H8: =IFERROR(G8/E8,0) -> 0.54083519 | I8: =_xlfn.TEXTJOIN(" + ",TRUE,IF(COUNTIFS(OrderLines!$A$2:$A$925,A8,OrderLines!$F$2:$F$925,"Beverage")>0,"Beverage",""),IF(COUNTIFS(OrderLines!$A$2:$A$925,A8,OrderLines!$F$2:$F$925,"Dessert")>0,"Dessert",""),IF(COUNTIFS(OrderLines!$A$2:$A$925,A8,OrderLines!$F$2:$F$925,"Hot Meal")>0,"Hot Meal",""),IF(COUNTIFS(OrderLines!$A$2:$A$925,A8,OrderLines!$F$2:$F$925,"Snack")>0,"Snack","")) -> Beverage + Hot Meal | K8: Beverage + Snack | L8: =COUNTIFS($I$2:$I$361,K8,$B$2:$B$361,IF('Dashboard '!$B$4="All","*",'Dashboard '!$B$4),$C$2:$C$361,IF('Dashboard '!$E$4="All","*",'Dashboard '!$E$4)) -> 31 | M8: =RANK(L8,$L$2:$L$16)+COUNTIF($L$2:L8,L8)-1 -> 2
A9: =Orders!A9 -> O00008 | B9: =Orders!C9 -> Plant 1 Canteen | C9: =Orders!F9 -> Lunch | D9: =Orders!J9 -> Single | E9: =Orders!I9 -> 223.75 | F9: =SUMIF(OrderLines!$A$2:$A$925,A9,OrderLines!$L$2:$L$925) -> 110.98 | G9: =E9-F9 -> 112.77 | H9: =IFERROR(G9/E9,0) -> 0.504 | I9: =_xlfn.TEXTJOIN(" + ",TRUE,IF(COUNTIFS(OrderLines!$A$2:$A$925,A9,OrderLines!$F$2:$F$925,"Beverage")>0,"Beverage",""),IF(COUNTIFS(OrderLines!$A$2:$A$925,A9,OrderLines!$F$2:$F$925,"Dessert")>0,"Dessert",""),IF(COUNTIFS(OrderLines!$A$2:$A$925,A9,OrderLines!$F$2:$F$925,"Hot Meal")>0,"Hot Meal",""),IF(COUNTIFS(OrderLines!$A$2:$A$925,A9,OrderLines!$F$2:$F$925,"Snack")>0,"Snack","")) -> Beverage + Dessert | K9: Dessert + Hot Meal | L9: =COUNTIFS($I$2:$I$361,K9,$B$2:$B$361,IF('Dashboard '!$B$4="All","*",'Dashboard '!$B$4),$C$2:$C$361,IF('Dashboard '!$E$4="All","*",'Dashboard '!$E$4)) -> 27 | M9: =RANK(L9,$L$2:$L$16)+COUNTIF($L$2:L9,L9)-1 -> 6
A10: =Orders!A10 -> O00009 | B10: =Orders!C10 -> Head Office Café | C10: =Orders!F10 -> Breakfast | D10: =Orders!J10 -> Single | E10: =Orders!I10 -> 459.2898 | F10: =SUMIF(OrderLines!$A$2:$A$925,A10,OrderLines!$L$2:$L$925) -> 225.97 | G10: =E10-F10 -> 233.3198 | H10: =IFERROR(G10/E10,0) -> 0.50800127 | I10: =_xlfn.TEXTJOIN(" + ",TRUE,IF(COUNTIFS(OrderLines!$A$2:$A$925,A10,OrderLines!$F$2:$F$925,"Beverage")>0,"Beverage",""),IF(COUNTIFS(OrderLines!$A$2:$A$925,A10,OrderLines!$F$2:$F$925,"Dessert")>0,"Dessert",""),IF(COUNTIFS(OrderLines!$A$2:$A$925,A10,OrderLines!$F$2:$F$925,"Hot Meal")>0,"Hot Meal",""),IF(COUNTIFS(OrderLines!$A$2:$A$925,A10,OrderLines!$F$2:$F$925,"Snack")>0,"Snack","")) -> Dessert + Hot Meal + Snack | K10: Dessert + Snack | L10: =COUNTIFS($I$2:$I$361,K10,$B$2:$B$361,IF('Dashboard '!$B$4="All","*",'Dashboard '!$B$4),$C$2:$C$361,IF('Dashboard '!$E$4="All","*",'Dashboard '!$E$4)) -> 18 | M10: =RANK(L10,$L$2:$L$16)+COUNTIF($L$2:L10,L10)-1 -> 13
A11: =Orders!A11 -> O00010 | B11: =Orders!C11 -> Plant 1 Canteen | C11: =Orders!F11 -> Breakfast | D11: =Orders!J11 -> Combo | E11: =Orders!I11 -> 420.0768 | F11: =SUMIF(OrderLines!$A$2:$A$925,A11,OrderLines!$L$2:$L$925) -> 204.88 | G11: =E11-F11 -> 215.1968 | H11: =IFERROR(G11/E11,0) -> 0.51227966 | I11: =_xlfn.TEXTJOIN(" + ",TRUE,IF(COUNTIFS(OrderLines!$A$2:$A$925,A11,OrderLines!$F$2:$F$925,"Beverage")>0,"Beverage",""),IF(COUNTIFS(OrderLines!$A$2:$A$925,A11,OrderLines!$F$2:$F$925,"Dessert")>0,"Dessert",""),IF(COUNTIFS(OrderLines!$A$2:$A$925,A11,OrderLines!$F$2:$F$925,"Hot Meal")>0,"Hot Meal",""),IF(COUNTIFS(OrderLines!$A$2:$A$925,A11,OrderLines!$F$2:$F$925,"Snack")>0,"Snack","")) -> Beverage + Dessert + Hot Meal + Snack | K11: Hot Meal + Snack | L11: =COUNTIFS($I$2:$I$361,K11,$B$2:$B$361,IF('Dashboard '!$B$4="All","*",'Dashboard '!$B$4),$C$2:$C$361,IF('Dashboard '!$E$4="All","*",'Dashboard '!$E$4)) -> 28 | M11: =RANK(L11,$L$2:$L$16)+COUNTIF($L$2:L11,L11)-1 -> 4
A12: =Orders!A12 -> O00011 | B12: =Orders!C12 -> Plant 2 Canteen | C12: =Orders!F12 -> Breakfast | D12: =Orders!J12 -> Single | E12: =Orders!I12 -> 27.5771 | F12: =SUMIF(OrderLines!$A$2:$A$925,A12,OrderLines!$L$2:$L$925) -> 13.89 | G12: =E12-F12 -> 13.6871 | H12: =IFERROR(G12/E12,0) -> 0.49632122 | I12: =_xlfn.TEXTJOIN(" + ",TRUE,IF(COUNTIFS(OrderLines!$A$2:$A$925,A12,OrderLines!$F$2:$F$925,"Beverage")>0,"Beverage",""),IF(COUNTIFS(OrderLines!$A$2:$A$925,A12,OrderLines!$F$2:$F$925,"Dessert")>0,"Dessert",""),IF(COUNTIFS(OrderLines!$A$2:$A$925,A12,OrderLines!$F$2:$F$925,"Hot Meal")>0,"Hot Meal",""),IF(COUNTIFS(OrderLines!$A$2:$A$925,A12,OrderLines!$F$2:$F$925,"Snack")>0,"Snack","")) -> Beverage | K12: Beverage + Dessert + Hot Meal | L12: =COUNTIFS($I$2:$I$361,K12,$B$2:$B$361,IF('Dashboard '!$B$4="All","*",'Dashboard '!$B$4),$C$2:$C$361,IF('Dashboard '!$E$4="All","*",'Dashboard '!$E$4)) -> 27 | M12: =RANK(L12,$L$2:$L$16)+COUNTIF($L$2:L12,L12)-1 -> 7
A13: =Orders!A13 -> O00012 | B13: =Orders!C13 -> Plant 2 Canteen | C13: =Orders!F13 -> Lunch | D13: =Orders!J13 -> Single | E13: =Orders!I13 -> 98.118 | F13: =SUMIF(OrderLines!$A$2:$A$925,A13,OrderLines!$L$2:$L$925) -> 47.75 | G13: =E13-F13 -> 50.368 | H13: =IFERROR(G13/E13,0) -> 0.51334108 | I13: =_xlfn.TEXTJOIN(" + ",TRUE,IF(COUNTIFS(OrderLines!$A$2:$A$925,A13,OrderLines!$F$2:$F$925,"Beverage")>0,"Beverage",""),IF(COUNTIFS(OrderLines!$A$2:$A$925,A13,OrderLines!$F$2:$F$925,"Dessert")>0,"Dessert",""),IF(COUNTIFS(OrderLines!$A$2:$A$925,A13,OrderLines!$F$2:$F$925,"Hot Meal")>0,"Hot Meal",""),IF(COUNTIFS(OrderLines!$A$2:$A$925,A13,OrderLines!$F$2:$F$925,"Snack")>0,"Snack","")) -> Dessert + Snack | K13: Beverage + Dessert + Snack | L13: =COUNTIFS($I$2:$I$361,K13,$B$2:$B$361,IF('Dashboard '!$B$4="All","*",'Dashboard '!$B$4),$C$2:$C$361,IF('Dashboard '!$E$4="All","*",'Dashboard '!$E$4)) -> 22 | M13: =RANK(L13,$L$2:$L$16)+COUNTIF($L$2:L13,L13)-1 -> 12
... A16: =Orders!A16 -> O00015 | B16: =Orders!C16 -> Head Office Café | C16: =Orders!F16 -> Lunch | D16: =Orders!J16 -> Combo | E16: =Orders!I16 -> 410.1839 | F16: =SUMIF(OrderLines!$A$2:$A$925,A16,OrderLines!$L$2:$L$925) -> 186.05 | G16: =E16-F16 -> 224.1339 | H16: =IFERROR(G16/E16,0) -> 0.54642296 | I16: =_xlfn.TEXTJOIN(" + ",TRUE,IF(COUNTIFS(OrderLines!$A$2:$A$925,A16,OrderLines!$F$2:$F$925,"Beverage")>0,"Beverage",""),IF(COUNTIFS(OrderLines!$A$2:$A$925,A16,OrderLines!$F$2:$F$925,"Dessert")>0,"Dessert",""),IF(COUNTIFS(OrderLines!$A$2:$A$925,A16,OrderLines!$F$2:$F$925,"Hot Meal")>0,"Hot Meal",""),IF(COUNTIFS(OrderLines!$A$2:$A$925,A16,OrderLines!$F$2:$F$925,"Snack")>0,"Snack","")) -> Beverage + Dessert + Hot Meal | K16: Beverage + Dessert + Hot Meal + Snack | L16: =COUNTIFS($I$2:$I$361,K16,$B$2:$B$361,IF('Dashboard '!$B$4="All","*",'Dashboard '!$B$4),$C$2:$C$361,IF('Dashboard '!$E$4="All","*",'Dashboard '!$E$4)) -> 9 | M16: =RANK(L16,$L$2:$L$16)+COUNTIF($L$2:L16,L16)-1 -> 15
A17: =Orders!A17 -> O00016 | B17: =Orders!C17 -> Plant 1 Canteen | C17: =Orders!F17 -> Dinner | D17: =Orders!J17 -> Single | E17: =Orders!I17 -> 486.9415 | F17: =SUMIF(OrderLines!$A$2:$A$925,A17,OrderLines!$L$2:$L$925) -> 238.57 | G17: =E17-F17 -> 248.3715 | H17: =IFERROR(G17/E17,0) -> 0.51006435 | I17: =_xlfn.TEXTJOIN(" + ",TRUE,IF(COUNTIFS(OrderLines!$A$2:$A$925,A17,OrderLines!$F$2:$F$925,"Beverage")>0,"Beverage",""),IF(COUNTIFS(OrderLines!$A$2:$A$925,A17,OrderLines!$F$2:$F$925,"Dessert")>0,"Dessert",""),IF(COUNTIFS(OrderLines!$A$2:$A$925,A17,OrderLines!$F$2:$F$925,"Hot Meal")>0,"Hot Meal",""),IF(COUNTIFS(OrderLines!$A$2:$A$925,A17,OrderLines!$F$2:$F$925,"Snack")>0,"Snack","")) -> Dessert + Hot Meal + Snack
A18: =Orders!A18 -> O00017 | B18: =Orders!C18 -> Plant 1 Canteen | C18: =Orders!F18 -> Dinner | D18: =Orders!J18 -> Single | E18: =Orders!I18 -> 30.6714 | F18: =SUMIF(OrderLines!$A$2:$A$925,A18,OrderLines!$L$2:$L$925) -> 11.84 | G18: =E18-F18 -> 18.8314 | H18: =IFERROR(G18/E18,0) -> 0.61397263 | I18: =_xlfn.TEXTJOIN(" + ",TRUE,IF(COUNTIFS(OrderLines!$A$2:$A$925,A18,OrderLines!$F$2:$F$925,"Beverage")>0,"Beverage",""),IF(COUNTIFS(OrderLines!$A$2:$A$925,A18,OrderLines!$F$2:$F$925,"Dessert")>0,"Dessert",""),IF(COUNTIFS(OrderLines!$A$2:$A$925,A18,OrderLines!$F$2:$F$925,"Hot Meal")>0,"Hot Meal",""),IF(COUNTIFS(OrderLines!$A$2:$A$925,A18,OrderLines!$F$2:$F$925,"Snack")>0,"Snack","")) -> Beverage
A19: =Orders!A19 -> O00018 | B19: =Orders!C19 -> Plant 1 Canteen | C19: =Orders!F19 -> Breakfast | D19: =Orders!J19 -> Single | E19: =Orders!I19 -> 164.484 | F19: =SUMIF(OrderLines!$A$2:$A$925,A19,OrderLines!$L$2:$L$925) -> 72.65 | G19: =E19-F19 -> 91.834 | H19: =IFERROR(G19/E19,0) -> 0.5583157 | I19: =_xlfn.TEXTJOIN(" + ",TRUE,IF(COUNTIFS(OrderLines!$A$2:$A$925,A19,OrderLines!$F$2:$F$925,"Beverage")>0,"Beverage",""),IF(COUNTIFS(OrderLines!$A$2:$A$925,A19,OrderLines!$F$2:$F$925,"Dessert")>0,"Dessert",""),IF(COUNTIFS(OrderLines!$A$2:$A$925,A19,OrderLines!$F$2:$F$925,"Hot Meal")>0,"Hot Meal",""),IF(COUNTIFS(OrderLines!$A$2:$A$925,A19,OrderLines!$F$2:$F$925,"Snack")>0,"Snack","")) -> Beverage + Dessert
A20: =Orders!A20 -> O00019 | B20: =Orders!C20 -> Plant 1 Canteen | C20: =Orders!F20 -> Breakfast | D20: =Orders!J20 -> Single | E20: =Orders!I20 -> 701.5296 | F20: =SUMIF(OrderLines!$A$2:$A$925,A20,OrderLines!$L$2:$L$925) -> 359.21 | G20: =E20-F20 -> 342.3196 | H20: =IFERROR(G20/E20,0) -> 0.48796173 | I20: =_xlfn.TEXTJOIN(" + ",TRUE,IF(COUNTIFS(OrderLines!$A$2:$A$925,A20,OrderLines!$F$2:$F$925,"Beverage")>0,"Beverage",""),IF(COUNTIFS(OrderLines!$A$2:$A$925,A20,OrderLines!$F$2:$F$925,"Dessert")>0,"Dessert",""),IF(COUNTIFS(OrderLines!$A$2:$A$925,A20,OrderLines!$F$2:$F$925,"Hot Meal")>0,"Hot Meal",""),IF(COUNTIFS(OrderLines!$A$2:$A$925,A20,OrderLines!$F$2:$F$925,"Snack")>0,"Snack","")) -> Hot Meal + Snack
A21: =Orders!A21 -> O00020 | B21: =Orders!C21 -> Plant 2 Canteen | C21: =Orders!F21 -> Breakfast | D21: =Orders!J21 -> Combo | E21: =Orders!I21 -> 474.753 | F21: =SUMIF(OrderLines!$A$2:$A$925,A21,OrderLines!$L$2:$L$925) -> 212.14 | G21: =E21-F21 -> 262.613 | H21: =IFERROR(G21/E21,0) -> 0.55315712 | I21: =_xlfn.TEXTJOIN(" + ",TRUE,IF(COUNTIFS(OrderLines!$A$2:$A$925,A21,OrderLines!$F$2:$F$925,"Beverage")>0,"Beverage",""),IF(COUNTIFS(OrderLines!$A$2:$A$925,A21,OrderLines!$F$2:$F$925,"Dessert")>0,"Dessert",""),IF(COUNTIFS(OrderLines!$A$2:$A$925,A21,OrderLines!$F$2:$F$925,"Hot Meal")>0,"Hot Meal",""),IF(COUNTIFS(OrderLines!$A$2:$A$925,A21,OrderLines!$F$2:$F$925,"Snack")>0,"Snack","")) -> Beverage + Dessert + Hot Meal
A22: =Orders!A22 -> O00021 | B22: =Orders!C22 -> Plant 2 Canteen | C22: =Orders!F22 -> Dinner | D22: =Orders!J22 -> Single | E22: =Orders!I22 -> 291.7264 | F22: =SUMIF(OrderLines!$A$2:$A$925,A22,OrderLines!$L$2:$L$925) -> 138.13 | G22: =E22-F22 -> 153.5964 | H22: =IFERROR(G22/E22,0) -> 0.5265084 | I22: =_xlfn.TEXTJOIN(" + ",TRUE,IF(COUNTIFS(OrderLines!$A$2:$A$925,A22,OrderLines!$F$2:$F$925,"Beverage")>0,"Beverage",""),IF(COUNTIFS(OrderLines!$A$2:$A$925,A22,OrderLines!$F$2:$F$925,"Dessert")>0,"Dessert",""),IF(COUNTIFS(OrderLines!$A$2:$A$925,A22,OrderLines!$F$2:$F$925,"Hot Meal")>0,"Hot Meal",""),IF(COUNTIFS(OrderLines!$A$2:$A$925,A22,OrderLines!$F$2:$F$925,"Snack")>0,"Snack","")) -> Snack
A23: =Orders!A23 -> O00022 | B23: =Orders!C23 -> Plant 2 Canteen | C23: =Orders!F23 -> Breakfast | D23: =Orders!J23 -> Combo | E23: =Orders!I23 -> 364.2903 | F23: =SUMIF(OrderLines!$A$2:$A$925,A23,OrderLines!$L$2:$L$925) -> 170.97 | G23: =E23-F23 -> 193.3203 | H23: =IFERROR(G23/E23,0) -> 0.5306765 | I23: =_xlfn.TEXTJOIN(" + ",TRUE,IF(COUNTIFS(OrderLines!$A$2:$A$925,A23,OrderLines!$F$2:$F$925,"Beverage")>0,"Beverage",""),IF(COUNTIFS(OrderLines!$A$2:$A$925,A23,OrderLines!$F$2:$F$925,"Dessert")>0,"Dessert",""),IF(COUNTIFS(OrderLines!$A$2:$A$925,A23,OrderLines!$F$2:$F$925,"Hot Meal")>0,"Hot Meal",""),IF(COUNTIFS(OrderLines!$A$2:$A$925,A23,OrderLines!$F$2:$F$925,"Snack")>0,"Snack","")) -> Beverage + Dessert + Hot Meal
A24: =Orders!A24 -> O00023 | B24: =Orders!C24 -> Plant 2 Canteen | C24: =Orders!F24 -> Lunch | D24: =Orders!J24 -> Combo | E24: =Orders!I24 -> 242.242 | F24: =SUMIF(OrderLines!$A$2:$A$925,A24,OrderLines!$L$2:$L$925) -> 120.08 | G24: =E24-F24 -> 122.162 | H24: =IFERROR(G24/E24,0) -> 0.50429736 | I24: =_xlfn.TEXTJOIN(" + ",TRUE,IF(COUNTIFS(OrderLines!$A$2:$A$925,A24,OrderLines!$F$2:$F$925,"Beverage")>0,"Beverage",""),IF(COUNTIFS(OrderLines!$A$2:$A$925,A24,OrderLines!$F$2:$F$925,"Dessert")>0,"Dessert",""),IF(COUNTIFS(OrderLines!$A$2:$A$925,A24,OrderLines!$F$2:$F$925,"Hot Meal")>0,"Hot Meal",""),IF(COUNTIFS(OrderLines!$A$2:$A$925,A24,OrderLines!$F$2:$F$925,"Snack")>0,"Snack","")) -> Beverage + Hot Meal
A25: =Orders!A25 -> O00024 | B25: =Orders!C25 -> Plant 1 Canteen | C25: =Orders!F25 -> Dinner | D25: =Orders!J25 -> Single | E25: =Orders!I25 -> 390.888 | F25: =SUMIF(OrderLines!$A$2:$A$925,A25,OrderLines!$L$2:$L$925) -> 242.76 | G25: =E25-F25 -> 148.128 | H25: =IFERROR(G25/E25,0) -> 0.37895254 | I25: =_xlfn.TEXTJOIN(" + ",TRUE,IF(COUNTIFS(OrderLines!$A$2:$A$925,A25,OrderLines!$F$2:$F$925,"Beverage")>0,"Beverage",""),IF(COUNTIFS(OrderLines!$A$2:$A$925,A25,OrderLines!$F$2:$F$925,"Dessert")>0,"Dessert",""),IF(COUNTIFS(OrderLines!$A$2:$A$925,A25,OrderLines!$F$2:$F$925,"Hot Meal")>0,"Hot Meal",""),IF(COUNTIFS(OrderLines!$A$2:$A$925,A25,OrderLines!$F$2:$F$925,"Snack")>0,"Snack","")) -> Hot Meal
A26: =Orders!A26 -> O00025 | B26: =Orders!C26 -> Plant 2 Canteen | C26: =Orders!F26 -> Breakfast | D26: =Orders!J26 -> Single | E26: =Orders!I26 -> 47.1786 | F26: =SUMIF(OrderLines!$A$2:$A$925,A26,OrderLines!$L$2:$L$925) -> 22.61 | G26: =E26-F26 -> 24.5686 | H26: =IFERROR(G26/E26,0) -> 0.52075729 | I26: =_xlfn.TEXTJOIN(" + ",TRUE,IF(COUNTIFS(OrderLines!$A$2:$A$925,A26,OrderLines!$F$2:$F$925,"Beverage")>0,"Beverage",""),IF(COUNTIFS(OrderLines!$A$2:$A$925,A26,OrderLines!$F$2:$F$925,"Dessert")>0,"Dessert",""),IF(COUNTIFS(OrderLines!$A$2:$A$925,A26,OrderLines!$F$2:$F$925,"Hot Meal")>0,"Hot Meal",""),IF(COUNTIFS(OrderLines!$A$2:$A$925,A26,OrderLines!$F$2:$F$925,"Snack")>0,"Snack","")) -> Snack
A27: =Orders!A27 -> O00026 | B27: =Orders!C27 -> Plant 2 Canteen | C27: =Orders!F27 -> Dinner | D27: =Orders!J27 -> Single | E27: =Orders!I27 -> 81.459 | F27: =SUMIF(OrderLines!$A$2:$A$925,A27,OrderLines!$L$2:$L$925) -> 45.35 | G27: =E27-F27 -> 36.109 | H27: =IFERROR(G27/E27,0) -> 0.44327821 | I27: =_xlfn.TEXTJOIN(" + ",TRUE,IF(COUNTIFS(OrderLines!$A$2:$A$925,A27,OrderLines!$F$2:$F$925,"Beverage")>0,"Beverage",""),IF(COUNTIFS(OrderLines!$A$2:$A$925,A27,OrderLines!$F$2:$F$925,"Dessert")>0,"Dessert",""),IF(COUNTIFS(OrderLines!$A$2:$A$925,A27,OrderLines!$F$2:$F$925,"Hot Meal")>0,"Hot Meal",""),IF(COUNTIFS(OrderLines!$A$2:$A$925,A27,OrderLines!$F$2:$F$925,"Snack")>0,"Snack","")) -> Snack
A28: =Orders!A28 -> O00027 | B28: =Orders!C28 -> Head Office Café | C28: =Orders!F28 -> Dinner | D28: =Orders!J28 -> Combo | E28: =Orders!I28 -> 839.8458 | F28: =SUMIF(OrderLines!$A$2:$A$925,A28,OrderLines!$L$2:$L$925) -> 406.75 | G28: =E28-F28 -> 433.0958 | H28: =IFERROR(G28/E28,0) -> 0.5156849 | I28: =_xlfn.TEXTJOIN(" + ",TRUE,IF(COUNTIFS(OrderLines!$A$2:$A$925,A28,OrderLines!$F$2:$F$925,"Beverage")>0,"Beverage",""),IF(COUNTIFS(OrderLines!$A$2:$A$925,A28,OrderLines!$F$2:$F$925,"Dessert")>0,"Dessert",""),IF(COUNTIFS(OrderLines!$A$2:$A$925,A28,OrderLines!$F$2:$F$925,"Hot Meal")>0,"Hot Meal",""),IF(COUNTIFS(OrderLines!$A$2:$A$925,A28,OrderLines!$F$2:$F$925,"Snack")>0,"Snack","")) -> Beverage + Dessert + Hot Meal
... A361: =Orders!A361 -> O00360 | B361: =Orders!C361 -> Plant 2 Canteen | C361: =Orders!F361 -> Dinner | D361: =Orders!J361 -> Combo | E361: =Orders!I361 -> 962.1504 | F361: =SUMIF(OrderLines!$A$2:$A$925,A361,OrderLines!$L$2:$L$925) -> 466.15 | G361: =E361-F361 -> 496.0004 | H361: =IFERROR(G361/E361,0) -> 0.51551234 | I361: =_xlfn.TEXTJOIN(" + ",TRUE,IF(COUNTIFS(OrderLines!$A$2:$A$925,A361,OrderLines!$F$2:$F$925,"Beverage")>0,"Beverage",""),IF(COUNTIFS(OrderLines!$A$2:$A$925,A361,OrderLines!$F$2:$F$925,"Dessert")>0,"Dessert",""),IF(COUNTIFS(OrderLines!$A$2:$A$925,A361,OrderLines!$F$2:$F$925,"Hot Meal")>0,"Hot Meal",""),IF(COUNTIFS(OrderLines!$A$2:$A$925,A361,OrderLines!$F$2:$F$925,"Snack")>0,"Snack","")) -> Beverage + Hot Meal
I362: =_xlfn.TEXTJOIN(" + ",TRUE,IF(COUNTIFS(OrderLines!$A$2:$A$925,A362,OrderLines!$F$2:$F$925,"Beverage")>0,"Beverage",""),IF(COUNTIFS(OrderLines!$A$2:$A$925,A362,OrderLines!$F$2:$F$925,"Dessert")>0,"Dessert",""),IF(COUNTIFS(OrderLines!$A$2:$A$925,A362,OrderLines!$F$2:$F$925,"Hot Meal")>0,"Hot Meal",""),IF(COUNTIFS(OrderLines!$A$2:$A$925,A362,OrderLines!$F$2:$F$925,"Snack")>0,"Snack",""))

Sheet Menu
A1: SKU | B1: ItemName | C1: Category | D1: SupplierID | E1: UnitCost | F1: UnitPrice
A2: HXAJI0 | B2: Veg Thali | C2: Hot Meal | D2: S009 | E2: 96.22 | F2: 227.61
A3: HDPBHS | B3: Chicken Thali | C3: Hot Meal | D3: S001 | E3: 121.24 | F3: 256.91
A4: HUZZPQ | B4: Rajma Chawal | C4: Hot Meal | D4: S005 | E4: 80.92 | F4: 146.4
A5: H3A3ZM | B5: Paneer Butter Masala + Naan | C5: Hot Meal | D5: S003 | E5: 74.07 | F5: 170.83
A6: HH1DNM | B6: Egg Curry + Rice | C6: Hot Meal | D6: S006 | E6: 112.08 | F6: 246.09
A7: SV30T9 | B7: Samosa | C7: Snack | D7: S007 | E7: 15.51 | F7: 39.95
A8: SCKW5N | B8: Veg Sandwich | C8: Snack | D8: S004 | E8: 35.81 | F8: 70.54
A9: SZBIKC | B9: Paneer Roll | C9: Snack | D9: S004 | E9: 19.55 | F9: 38.06
A10: S5NQ4F | B10: Masala Puff | C10: Snack | D10: S006 | E10: 22.61 | F10: 50.19
A11: SHJ7XV | B11: Poha | C11: Snack | D11: S003 | E11: 25.8 | F11: 52.45
A12: BTIQJ7 | B12: Tea | C12: Beverage | D12: S009 | E12: 14.18 | F12: 30.34
A13: BHL1C3 | B13: Coffee | C13: Beverage | D13: S006 | E13: 9.38 | F13: 22.2
... A20: DYTJXE | B20: Fruit Cup | C20: Dessert | D20: S007 | E20: 29.14 | F20: 57.07

Sheet Staff
A1: StaffID | B1: StaffName | C1: Role | D1: Branch | E1: HourlyRateINR
A2: E001 | B2: Tarun | C2: Cashier | D2: Plant 1 Canteen | E2: 151.58
A3: E002 | B3: Payal | C3: Cashier | D3: Head Office Café | E3: 129.61
A4: E003 | B4: Karan | C4: Cashier | D4: Head Office Café | E4: 100.98
A5: E004 | B5: Payal | C5: Cook | D5: Plant 1 Canteen | E5: 134.57
A6: E005 | B6: Vikram | C6: Cook | D6: Head Office Café | E6: 93.09
A7: E006 | B7: Rina | C7: Cashier | D7: Head Office Café | E7: 171.84
A8: E007 | B8: Sanjay | C8: Cook | D8: Plant 2 Canteen | E8: 113.29
A9: E008 | B9: Manish | C9: Cook | D9: Head Office Café | E9: 149.63
A10: E009 | B10: Pooja | C10: Server | D10: Head Office Café | E10: 118.05
A11: E010 | B11: Sourav | C11: Cashier | D11: Plant 1 Canteen | E11: 136.81
A12: E011 | B12: Neha | C12: Cashier | D12: Plant 2 Canteen | E12: 139.2
A13: E012 | B13: Amit | C13: Cook | D13: Head Office Café | E13: 106.64
... A19: E018 | B19: Payal | C19: Cashier | D19: Head Office Café | E19: 172.97

Sheet Inventory
A1: SKU | B1: OnHandQty | C1: ReorderPoint | D1: LeadTimeDays | E1: LastRestockDate
A2: HXAJI0 | B2: 198 | C2: 36 | D2: 3 | E2: 45876
A3: HDPBHS | B3: 152 | C3: 30 | D3: 6 | E3: 45861
A4: HUZZPQ | B4: 120 | C4: 25 | D4: 6 | E4: 45882
A5: H3A3ZM | B5: 130 | C5: 42 | D5: 4 | E5: 45864
A6: HH1DNM | B6: 176 | C6: 46 | D6: 3 | E6: 45871
A7: SV30T9 | B7: 81 | C7: 25 | D7: 3 | E7: 45868
A8: SCKW5N | B8: 45 | C8: 57 | D8: 4 | E8: 45840
A9: SZBIKC | B9: 89 | C9: 21 | D9: 5 | E9: 45864
A10: S5NQ4F | B10: 85 | C10: 41 | D10: 3 | E10: 45873
A11: SHJ7XV | B11: 80 | C11: 39 | D11: 2 | E11: 45861
A12: BTIQJ7 | B12: 84 | C12: 44 | D12: 4 | E12: 45845
A13: BHL1C3 | B13: 55 | C13: 34 | D13: 3 | E13: 45850
... A20: DYTJXE | B20: 53 | C20: 58 | D20: 5 | E20: 45850

Sheet Suppliers
A1: SupplierID | B1: SupplierName | C1: City | D1: Phone
A2: S001 | B2: DailyDairy 1 | C2: Howrah | D2: +91-9624636385
A3: S002 | B3: BakersHub 2 | C3: Durgapur | D3: +91-9120912992
A4: S003 | B4: FreshFoods 3 | C4: Durgapur | D4: +91-9220117054
A5: S004 | B5: Tea&Co 4 | C5: Jamshedpur | D5: +91-9489747629
A6: S005 | B6: SpiceRoute 5 | C6: Durgapur | D6: +91-9992994062
A7: S006 | B7: DailyDairy 6 | C7: Howrah | D7: +91-9966267851
A8: S007 | B8: SpiceRoute 7 | C8: Howrah | D8: +91-9430190783
A9: S008 | B9: AgroDelight 8 | C9: Kolkata | D9: +91-9357109965
A10: S009 | B10: Tea&Co 9 | C10: Howrah | D10: +91-9162196678
A11: S010 | B11: SpiceRoute 10 | C11: Jamshedpur | D11: +91-9358633898

Sheet WasteLog
A1: Date | B1: SKU | C1: Qty | D1: Reason
A2: 45867 | B2: BHL1C3 | C2: 2 | D2: Spoilage
A3: 45860 | B3: HH1DNM | C3: 4 | D3: Damaged
A4: 45853 | B4: B0T0PV | C4: 2 | D4: Expired
A5: 45879 | B5: D9T84A | C5: 2 | D5: Damaged
A6: 45891 | B6: SCKW5N | C6: 2 | D6: Spoilage
A7: 45896 | B7: HUZZPQ | C7: 1 | D7: Damaged
A8: 45890 | B8: BHL1C3 | C8: 3 | D8: Overproduction
A9: 45893 | B9: H3A3ZM | C9: 1 | D9: Overproduction
A10: 45892 | B10: DFFYVN | C10: 2 | D10: Spoilage
A11: 45894 | B11: D9T84A | C11: 1 | D11: Spoilage
A12: 45854 | B12: BTIQJ7 | C12: 1 | D12: Damaged
A13: 45850 | B13: SCKW5N | C13: 4 | D13: Damaged
... A121: 45847 | B121: SHJ7XV | C121: 2 | D121: Spoilage

Sheet Feedback
A1: Date | B1: Branch | C1: Rating | D1: Comment
A2: 45846 | B2: Plant 1 Canteen | C2: 4 | D2: Ok
A3: 45875 | B3: Head Office Café | C3: 3 | D3: Great staff
A4: 45869 | B4: Plant 2 Canteen | C4: 2 | D4: Good
A5: 45839 | B5: Plant 2 Canteen | C5: 5 | D5: Less spicy
A6: 45865 | B6: Plant 1 Canteen | C6: 3 | D6: Good
A7: 45857 | B7: Plant 2 Canteen | C7: 5 | D7: Great staff
A8: 45849 | B8: Plant 1 Canteen | C8: 2 | D8: Less spicy
A9: 45892 | B9: Plant 1 Canteen | C9: 4 | D9: Great staff
A10: 45840 | B10: Plant 2 Canteen | C10: 5 | D10: Great staff
A11: 45847 | B11: Head Office Café | C11: 3 | D11: Ok
A12: 45875 | B12: Plant 1 Canteen | C12: 3 | D12: Loved chai
A13: 45868 | B13: Plant 2 Canteen | C13: 5 | D13: Ok
... A17: 45896 | B17: Head Office Café | C17: 3 | D17: Crowded
A18: 45849 | B18: Plant 1 Canteen | C18: 4
A19: 45877 | B19: Plant 2 Canteen | C19: 5 | D19: Less spicy
A20: 45881 | B20: Plant 2 Canteen | C20: 5 | D20: Ok
A21: 45868 | B21: Plant 2 Canteen | C21: 3 | D21: Crowded
A22: 45869 | B22: Plant 1 Canteen | C22: 5 | D22: Less spicy
A23: 45867 | B23: Head Office Café | C23: 5 | D23: Slow service
A24: 45870 | B24: Plant 2 Canteen | C24: 4 | D24: Great staff
A25: 45874 | B25: Plant 1 Canteen | C25: 3 | D25: Ok
A26: 45892 | B26: Plant 1 Canteen | C26: 5 | D26: Slow service
A27: 45881 | B27: Plant 2 Canteen | C27: 2 | D27: Great staff
A28: 45887 | B28: Plant 1 Canteen | C28: 4 | D28: Slow service
A29: 45863 | B29: Head Office Café | C29: 3 | D29: Great staff
A30: 45875 | B30: Plant 1 Canteen | C30: 5 | D30: Crowded
A31: 45895 | B31: Plant 2 Canteen | C31: 5
A32: 45873 | B32: Head Office Café | C32: 2 | D32: Good
A33: 45863 | B33: Head Office Café | C33: 4 | D33: Ok
A34: 45843 | B34: Head Office Café | C34: 5 | D34: Less spicy
A35: 45880 | B35: Plant 1 Canteen | C35: 2 | D35: Good
A36: 45864 | B36: Plant 1 Canteen | C36: 3 | D36: Crowded
A37: 45875 | B37: Plant 2 Canteen | C37: 5 | D37: Ok
A38: 45872 | B38: Plant 1 Canteen | C38: 5 | D38: Good
A39: 45867 | B39: Plant 2 Canteen | C39: 2 | D39: Good
A40: 45852 | B40: Plant 2 Canteen | C40: 4 | D40: Less spicy
A41: 45883 | B41: Plant 1 Canteen | C41: 5 | D41: Less spicy
A42: 45885 | B42: Plant 1 Canteen | C42: 5 | D42: Crowded
A43: 45869 | B43: Plant 1 Canteen | C43: 4
...

Sheet KPI Calculations (Day 2)
A1: 2) Monthly Revenue & Month-on-Month Change | B1: Value
A2: July revenue: | B2: =SUMIFS(OrderLines!I:I, OrderLines!G:G, ">="&DATE(2025,7,1), OrderLines!G:G, "<"&DATE(2025,8,1)) -> 63939.191
A3: August revenue: | B3: =SUMIFS(OrderLines!I:I, OrderLines!G:G, ">="&DATE(2025,8,1), OrderLines!G:G, "<"&DATE(2025,9,1)) -> 68708.44
A4: MOM: | B4: =(B3-B2)/B2 -> 0.07459039
A6: 3) Lunch shift Revenue in August 2025 for Head Office Café | B6: Value
A7: Lunch Revenue: | B7: =SUMIFS(OrderLines!I:I, OrderLines!G:G,">="&DATE(2025,8,1), OrderLines!G:G,"<"&DATE(2025,9,1), OrderLines!H:H,"Head Office Café", OrderLines!J:J,"Lunch") -> 7403.6595
A9: 4) Orders with any Beverage item and paid via UPI | B9: Value
A10: Beverage + UPI count: | B10: =COUNTIFS(Orders!H:H,TRUE,Orders!E:E,"UPI") -> 70
A12: 5) Average ticket size by Shift for July and August combined | B12: Value
A13: Breakfast | B13: =AVERAGEIFS(Orders!I:I, Orders!F:F,"Breakfast", Orders!B:B,">="&DATE(2025,7,1), Orders!B:B,"<"&DATE(2025,9,1)) -> 360.57145
A14: Lunch | B14: =AVERAGEIFS(Orders!I:I, Orders!F:F,"Lunch", Orders!B:B,">="&DATE(2025,7,1), Orders!B:B,"<"&DATE(2025,9,1)) -> 372.02587
A15: Dinner | B15: =AVERAGEIFS(Orders!I:I, Orders!F:F,"Dinner", Orders!B:B,">="&DATE(2025,7,1), Orders!B:B,"<"&DATE(2025,9,1)) -> 378.80541

Sheet Gross Margin Analysis (Day 4 )
A1: 1) Revenue by Category and Branch for July plus August
A3: Category | B3: Head Office Café | C3: Plant 1 Canteen | D3: Plant 2 Canteen | E3: Total Revenue | F3: Head Office Café % Contribution | G3: Plant 1 Canteen % Contribution | H3: Plant 2 Canteen % Contribution
A4: Hot Meal | B4: =SUMIFS(OrderLines!$I:$I, OrderLines!$F:$F, $A4, OrderLines!$H:$H, B$3, OrderLines!$G:$G, ">="&DATE(2025,7,1), OrderLines!$G:$G, "<"&DATE(2025,9,1)) -> 30604.808 | C4: =SUMIFS(OrderLines!$I:$I, OrderLines!$F:$F, $A4, OrderLines!$H:$H, C$3, OrderLines!$G:$G, ">="&DATE(2025,7,1), OrderLines!$G:$G, "<"&DATE(2025,9,1)) -> 17407.726 | D4: =SUMIFS(OrderLines!$I:$I, OrderLines!$F:$F, $A4, OrderLines!$H:$H, D$3, OrderLines!$G:$G, ">="&DATE(2025,7,1), OrderLines!$G:$G, "<"&DATE(2025,9,1)) -> 31124.138 | E4: =SUM(B4:D4) -> 79136.671 | F4: =IFERROR(B4/E4,0) -> 0.38673358 | G4: =IFERROR(C4/E4,0) -> 0.21997041 | H4: =IFERROR(D4/E4,0) -> 0.39329602
A5: Snack | B5: =SUMIFS(OrderLines!$I:$I, OrderLines!$F:$F, $A5, OrderLines!$H:$H, B$3, OrderLines!$G:$G, ">="&DATE(2025,7,1), OrderLines!$G:$G, "<"&DATE(2025,9,1)) -> 5343.449 | C5: =SUMIFS(OrderLines!$I:$I, OrderLines!$F:$F, $A5, OrderLines!$H:$H, C$3, OrderLines!$G:$G, ">="&DATE(2025,7,1), OrderLines!$G:$G, "<"&DATE(2025,9,1)) -> 6448.5657 | D5: =SUMIFS(OrderLines!$I:$I, OrderLines!$F:$F, $A5, OrderLines!$H:$H, D$3, OrderLines!$G:$G, ">="&DATE(2025,7,1), OrderLines!$G:$G, "<"&DATE(2025,9,1)) -> 6840.9941 | E5: =SUM(B5:D5) -> 18633.009 | F5: =IFERROR(B5/E5,0) -> 0.28677328 | G5: =IFERROR(C5/E5,0) -> 0.3460829 | H5: =IFERROR(D5/E5,0) -> 0.36714382
A6: Beverage | B6: =SUMIFS(OrderLines!$I:$I, OrderLines!$F:$F, $A6, OrderLines!$H:$H, B$3, OrderLines!$G:$G, ">="&DATE(2025,7,1), OrderLines!$G:$G, "<"&DATE(2025,9,1)) -> 3489.8727 | C6: =SUMIFS(OrderLines!$I:$I, OrderLines!$F:$F, $A6, OrderLines!$H:$H, C$3, OrderLines!$G:$G, ">="&DATE(2025,7,1), OrderLines!$G:$G, "<"&DATE(2025,9,1)) -> 2895.3357 | D6: =SUMIFS(OrderLines!$I:$I, OrderLines!$F:$F, $A6, OrderLines!$H:$H, D$3, OrderLines!$G:$G, ">="&DATE(2025,7,1), OrderLines!$G:$G, "<"&DATE(2025,9,1)) -> 3936.5499 | E6: =SUM(B6:D6) -> 10321.758 | F6: =IFERROR(B6/E6,0) -> 0.33810835 | G6: =IFERROR(C6/E6,0) -> 0.28050799 | H6: =IFERROR(D6/E6,0) -> 0.38138365
A7: Dessert | B7: =SUMIFS(OrderLines!$I:$I, OrderLines!$F:$F, $A7, OrderLines!$H:$H, B$3, OrderLines!$G:$G, ">="&DATE(2025,7,1), OrderLines!$G:$G, "<"&DATE(2025,9,1)) -> 9544.0172 | C7: =SUMIFS(OrderLines!$I:$I, OrderLines!$F:$F, $A7, OrderLines!$H:$H, C$3, OrderLines!$G:$G, ">="&DATE(2025,7,1), OrderLines!$G:$G, "<"&DATE(2025,9,1)) -> 6497.6642 | D7: =SUMIFS(OrderLines!$I:$I, OrderLines!$F:$F, $A7, OrderLines!$H:$H, D$3, OrderLines!$G:$G, ">="&DATE(2025,7,1), OrderLines!$G:$G, "<"&DATE(2025,9,1)) -> 8514.5112 | E7: =SUM(B7:D7) -> 24556.193 | F7: =IFERROR(B7/E7,0) -> 0.3886603 | G7: =IFERROR(C7/E7,0) -> 0.26460389 | H7: =IFERROR(D7/E7,0) -> 0.3467358
A8: Grand Total | B8: =SUM(B4:B7) -> 48982.147 | C8: =SUM(C4:C7) -> 33249.291 | D8: =SUM(D4:D7) -> 50416.193 | E8: =SUM(E4:E7) -> 132647.63
A11: 2) Top 10 SKUs by Revenue in August only
A13: Rank | B13: SKU | C13: ItemName | D13: Qty Sold | E13: Revenue | J13: Helper: SKU | K13: Helper: Aug Revenue
A14: 1 | B14: =INDEX($J$14:$J$32,MATCH($E14,$K$14:$K$32,0)) -> HXAJI0 | C14: =VLOOKUP(B14,Menu!$A:$B,2,FALSE()) -> Veg Thali | D14: =SUMIFS(OrderLines!$C:$C, OrderLines!$B:$B, B14, OrderLines!$G:$G, ">="&DATE(2025,8,1), OrderLines!$G:$G, "<"&DATE(2025,9,1)) -> 49 | E14: =LARGE($K$14:$K$32,$A14) -> 10470.06 | J14: =Menu!A2 -> HXAJI0 | K14: =SUMIFS(OrderLines!$I:$I, OrderLines!$B:$B, J14, OrderLines!$G:$G, ">="&DATE(2025,8,1), OrderLines!$G:$G, "<"&DATE(2025,9,1)) -> 10470.06
A15: 2 | B15: =INDEX($J$14:$J$32,MATCH($E15,$K$14:$K$32,0)) -> HDPBHS | C15: =VLOOKUP(B15,Menu!$A:$B,2,FALSE()) -> Chicken Thali | D15: =SUMIFS(OrderLines!$C:$C, OrderLines!$B:$B, B15, OrderLines!$G:$G, ">="&DATE(2025,8,1), OrderLines!$G:$G, "<"&DATE(2025,9,1)) -> 38 | E15: =LARGE($K$14:$K$32,$A15) -> 9230.7763 | J15: =Menu!A3 -> HDPBHS | K15: =SUMIFS(OrderLines!$I:$I, OrderLines!$B:$B, J15, OrderLines!$G:$G, ">="&DATE(2025,8,1), OrderLines!$G:$G, "<"&DATE(2025,9,1)) -> 9230.7763
A16: 3 | B16: =INDEX($J$14:$J$32,MATCH($E16,$K$14:$K$32,0)) -> HH1DNM | C16: =VLOOKUP(B16,Menu!$A:$B,2,FALSE()) -> Egg Curry + Rice | D16: =SUMIFS(OrderLines!$C:$C, OrderLines!$B:$B, B16, OrderLines!$G:$G, ">="&DATE(2025,8,1), OrderLines!$G:$G, "<"&DATE(2025,9,1)) -> 36 | E16: =LARGE($K$14:$K$32,$A16) -> 8283.3894 | J16: =Menu!A4 -> HUZZPQ | K16: =SUMIFS(OrderLines!$I:$I, OrderLines!$B:$B, J16, OrderLines!$G:$G, ">="&DATE(2025,8,1), OrderLines!$G:$G, "<"&DATE(2025,9,1)) -> 6563.112
A17: 4 | B17: =INDEX($J$14:$J$32,MATCH($E17,$K$14:$K$32,0)) -> HUZZPQ | C17: =VLOOKUP(B17,Menu!$A:$B,2,FALSE()) -> Rajma Chawal | D17: =SUMIFS(OrderLines!$C:$C, OrderLines!$B:$B, B17, OrderLines!$G:$G, ">="&DATE(2025,8,1), OrderLines!$G:$G, "<"&DATE(2025,9,1)) -> 48 | E17: =LARGE($K$14:$K$32,$A17) -> 6563.112 | J17: =Menu!A5 -> H3A3ZM | K17: =SUMIFS(OrderLines!$I:$I, OrderLines!$B:$B, J17, OrderLines!$G:$G, ">="&DATE(2025,8,1), OrderLines!$G:$G, "<"&DATE(2025,9,1)) -> 5927.801
A18: 5 | B18: =INDEX($J$14:$J$32,MATCH($E18,$K$14:$K$32,0)) -> H3A3ZM | C18: =VLOOKUP(B18,Menu!$A:$B,2,FALSE()) -> Paneer Butter Masala + Naan | D18: =SUMIFS(OrderLines!$C:$C, OrderLines!$B:$B, B18, OrderLines!$G:$G, ">="&DATE(2025,8,1), OrderLines!$G:$G, "<"&DATE(2025,9,1)) -> 37 | E18: =LARGE($K$14:$K$32,$A18) -> 5927.801 | J18: =Menu!A6 -> HH1DNM | K18: =SUMIFS(OrderLines!$I:$I, OrderLines!$B:$B, J18, OrderLines!$G:$G, ">="&DATE(2025,8,1), OrderLines!$G:$G, "<"&DATE(2025,9,1)) -> 8283.3894
A19: 6 | B19: =INDEX($J$14:$J$32,MATCH($E19,$K$14:$K$32,0)) -> D9T84A | C19: =VLOOKUP(B19,Menu!$A:$B,2,FALSE()) -> Brownie | D19: =SUMIFS(OrderLines!$C:$C, OrderLines!$B:$B, B19, OrderLines!$G:$G, ">="&DATE(2025,8,1), OrderLines!$G:$G, "<"&DATE(2025,9,1)) -> 45 | E19: =LARGE($K$14:$K$32,$A19) -> 4925.456 | J19: =Menu!A7 -> SV30T9 | K19: =SUMIFS(OrderLines!$I:$I, OrderLines!$B:$B, J19, OrderLines!$G:$G, ">="&DATE(2025,8,1), OrderLines!$G:$G, "<"&DATE(2025,9,1)) -> 1484.1425
A20: 7 | B20: =INDEX($J$14:$J$32,MATCH($E20,$K$14:$K$32,0)) -> DH9SDB | C20: =VLOOKUP(B20,Menu!$A:$B,2,FALSE()) -> Gulab Jamun (2 pc) | D20: =SUMIFS(OrderLines!$C:$C, OrderLines!$B:$B, B20, OrderLines!$G:$G, ">="&DATE(2025,8,1), OrderLines!$G:$G, "<"&DATE(2025,9,1)) -> 52 | E20: =LARGE($K$14:$K$32,$A20) -> 3714.9715 | J20: =Menu!A8 -> SCKW5N | K20: =SUMIFS(OrderLines!$I:$I, OrderLines!$B:$B, J20, OrderLines!$G:$G, ">="&DATE(2025,8,1), OrderLines!$G:$G, "<"&DATE(2025,9,1)) -> 2910.4804
A21: 8 | B21: =INDEX($J$14:$J$32,MATCH($E21,$K$14:$K$32,0)) -> SCKW5N | C21: =VLOOKUP(B21,Menu!$A:$B,2,FALSE()) -> Veg Sandwich | D21: =SUMIFS(OrderLines!$C:$C, OrderLines!$B:$B, B21, OrderLines!$G:$G, ">="&DATE(2025,8,1), OrderLines!$G:$G, "<"&DATE(2025,9,1)) -> 44 | E21: =LARGE($K$14:$K$32,$A21) -> 2910.4804 | J21: =Menu!A9 -> SZBIKC | K21: =SUMIFS(OrderLines!$I:$I, OrderLines!$B:$B, J21, OrderLines!$G:$G, ">="&DATE(2025,8,1), OrderLines!$G:$G, "<"&DATE(2025,9,1)) -> 1155.5016
A22: 9 | B22: =INDEX($J$14:$J$32,MATCH($E22,$K$14:$K$32,0)) -> DFFYVN | C22: =VLOOKUP(B22,Menu!$A:$B,2,FALSE()) -> Kheer Cup | D22: =SUMIFS(OrderLines!$C:$C, OrderLines!$B:$B, B22, OrderLines!$G:$G, ">="&DATE(2025,8,1), OrderLines!$G:$G, "<"&DATE(2025,9,1)) -> 46 | E22: =LARGE($K$14:$K$32,$A22) -> 2362.578 | J22: =Menu!A10 -> S5NQ4F | K22: =SUMIFS(OrderLines!$I:$I, OrderLines!$B:$B, J22, OrderLines!$G:$G, ">="&DATE(2025,8,1), OrderLines!$G:$G, "<"&DATE(2025,9,1)) -> 2318.778
A23: 10 | B23: =INDEX($J$14:$J$32,MATCH($E23,$K$14:$K$32,0)) -> S5NQ4F | C23: =VLOOKUP(B23,Menu!$A:$B,2,FALSE()) -> Masala Puff | D23: =SUMIFS(OrderLines!$C:$C, OrderLines!$B:$B, B23, OrderLines!$G:$G, ">="&DATE(2025,8,1), OrderLines!$G:$G, "<"&DATE(2025,9,1)) -> 49 | E23: =LARGE($K$14:$K$32,$A23) -> 2318.778 | J23: =Menu!A11 -> SHJ7XV | K23: =SUMIFS(OrderLines!$I:$I, OrderLines!$B:$B, J23, OrderLines!$G:$G, ">="&DATE(2025,8,1), OrderLines!$G:$G, "<"&DATE(2025,9,1)) -> 1563.5345
J24: =Menu!A12 -> BTIQJ7 | K24: =SUMIFS(OrderLines!$I:$I, OrderLines!$B:$B, J24, OrderLines!$G:$G, ">="&DATE(2025,8,1), OrderLines!$G:$G, "<"&DATE(2025,9,1)) -> 1508.5048
J25: =Menu!A13 -> BHL1C3 | K25: =SUMIFS(OrderLines!$I:$I, OrderLines!$B:$B, J25, OrderLines!$G:$G, ">="&DATE(2025,8,1), OrderLines!$G:$G, "<"&DATE(2025,9,1)) -> 647.796
A26: 3) Gross Margin% by Branch | J26: =Menu!A14 -> BOC6UZ | K26: =SUMIFS(OrderLines!$I:$I, OrderLines!$B:$B, J26, OrderLines!$G:$G, ">="&DATE(2025,8,1), OrderLines!$G:$G, "<"&DATE(2025,9,1)) -> 1432.6512
J27: =Menu!A15 -> BXO6QJ | K27: =SUMIFS(OrderLines!$I:$I, OrderLines!$B:$B, J27, OrderLines!$G:$G, ">="&DATE(2025,8,1), OrderLines!$G:$G, "<"&DATE(2025,9,1)) -> 854.8761
A28: Branch | B28: Revenue | C28: Food Cost | D28: Gross Margin | E28: Gross Margin% | J28: =Menu!A16 -> B0T0PV | K28: =SUMIFS(OrderLines!$I:$I, OrderLines!$B:$B, J28, OrderLines!$G:$G, ">="&DATE(2025,8,1), OrderLines!$G:$G, "<"&DATE(2025,9,1)) -> 1151.6993
A29: Head Office Café | B29: =SUMIFS(OrderLines!$I:$I, OrderLines!$H:$H, $A29) -> 48982.147 | C29: =SUMPRODUCT((OrderLines!$H$2:$H$925=$A29)*OrderLines!$C$2:$C$925*OrderLines!$E$2:$E$925) -> 24001.28 | D29: =B29-C29 -> 24980.867 | E29: =IFERROR(D29/B29,0) -> 0.50999942 | J29: =Menu!A17 -> DH9SDB | K29: =SUMIFS(OrderLines!$I:$I, OrderLines!$B:$B, J29, OrderLines!$G:$G, ">="&DATE(2025,8,1), OrderLines!$G:$G, "<"&DATE(2025,9,1)) -> 3714.9715
A30: Plant 1 Canteen | B30: =SUMIFS(OrderLines!$I:$I, OrderLines!$H:$H, $A30) -> 33249.291 | C30: =SUMPRODUCT((OrderLines!$H$2:$H$925=$A30)*OrderLines!$C$2:$C$925*OrderLines!$E$2:$E$925) -> 16720.52 | D30: =B30-C30 -> 16528.771 | E30: =IFERROR(D30/B30,0) -> 0.4971165 | J30: =Menu!A18 -> DFFYVN | K30: =SUMIFS(OrderLines!$I:$I, OrderLines!$B:$B, J30, OrderLines!$G:$G, ">="&DATE(2025,8,1), OrderLines!$G:$G, "<"&DATE(2025,9,1)) -> 2362.578
A31: Plant 2 Canteen | B31: =SUMIFS(OrderLines!$I:$I, OrderLines!$H:$H, $A31) -> 50416.193 | C31: =SUMPRODUCT((OrderLines!$H$2:$H$925=$A31)*OrderLines!$C$2:$C$925*OrderLines!$E$2:$E$925) -> 24427.5 | D31: =B31-C31 -> 25988.693 | E31: =IFERROR(D31/B31,0) -> 0.51548305 | J31: =Menu!A19 -> D9T84A | K31: =SUMIFS(OrderLines!$I:$I, OrderLines!$B:$B, J31, OrderLines!$G:$G, ">="&DATE(2025,8,1), OrderLines!$G:$G, "<"&DATE(2025,9,1)) -> 4925.456
J32: =Menu!A20 -> DYTJXE | K32: =SUMIFS(OrderLines!$I:$I, OrderLines!$B:$B, J32, OrderLines!$G:$G, ">="&DATE(2025,8,1), OrderLines!$G:$G, "<"&DATE(2025,9,1)) -> 2202.3313

Sheet Daily Performance (Day 5)
A1: Daily Performance
A3: Date | B3: Revenue | C3: Avg Feedback Rating | D3: Avg Waste Cost | E3: Risk
A4: =DATE(2025,7,1) -> 45839 | B4: =SUMIFS(Orders!$I:$I, Orders!$B:$B, ">="&$A4, Orders!$B:$B, "<"&($A4+1)) -> 198.822 | C4: =IFERROR(AVERAGEIFS(Feedback!$C:$C, Feedback!$A:$A, $A4),"") -> 3.8571429 | D4: =IFERROR(SUMPRODUCT((WasteLog!$A$2:$A$121=$A4)*WasteLog!$C$2:$C$121*IFERROR(VLOOKUP(WasteLog!$B$2:$B$121,Menu!$A:$E,5,FALSE()),0))/COUNTIFS(WasteLog!$A$2:$A$121,$A4),0) -> 0 | E4: =IF(OR($B4<1500, AND($C4<>"",$C4<3.2), IF($B4>0, $D4>0.04*$B4, $D4>0)), "At Risk", "OK") -> At Risk
A5: =A4+1 -> 45840 | B5: =SUMIFS(Orders!$I:$I, Orders!$B:$B, ">="&$A5, Orders!$B:$B, "<"&($A5+1)) -> 3202.85 | C5: =IFERROR(AVERAGEIFS(Feedback!$C:$C, Feedback!$A:$A, $A5),"") -> 3.6 | D5: =IFERROR(SUMPRODUCT((WasteLog!$A$2:$A$121=$A5)*WasteLog!$C$2:$C$121*IFERROR(VLOOKUP(WasteLog!$B$2:$B$121,Menu!$A:$E,5,FALSE()),0))/COUNTIFS(WasteLog!$A$2:$A$121,$A5),0) -> 85.6975 | E5: =IF(OR($B5<1500, AND($C5<>"",$C5<3.2), IF($B5>0, $D5>0.04*$B5, $D5>0)), "At Risk", "OK") -> OK
A6: =A5+1 -> 45841 | B6: =SUMIFS(Orders!$I:$I, Orders!$B:$B, ">="&$A6, Orders!$B:$B, "<"&($A6+1)) -> 1027.7541 | C6: =IFERROR(AVERAGEIFS(Feedback!$C:$C, Feedback!$A:$A, $A6),"") -> 4 | D6: =IFERROR(SUMPRODUCT((WasteLog!$A$2:$A$121=$A6)*WasteLog!$C$2:$C$121*IFERROR(VLOOKUP(WasteLog!$B$2:$B$121,Menu!$A:$E,5,FALSE()),0))/COUNTIFS(WasteLog!$A$2:$A$121,$A6),0) -> 0 | E6: =IF(OR($B6<1500, AND($C6<>"",$C6<3.2), IF($B6>0, $D6>0.04*$B6, $D6>0)), "At Risk", "OK") -> At Risk
A7: =A6+1 -> 45842 | B7: =SUMIFS(Orders!$I:$I, Orders!$B:$B, ">="&$A7, Orders!$B:$B, "<"&($A7+1)) -> 1622.0684 | C7: =IFERROR(AVERAGEIFS(Feedback!$C:$C, Feedback!$A:$A, $A7),"") -> 4.5 | D7: =IFERROR(SUMPRODUCT((WasteLog!$A$2:$A$121=$A7)*WasteLog!$C$2:$C$121*IFERROR(VLOOKUP(WasteLog!$B$2:$B$121,Menu!$A:$E,5,FALSE()),0))/COUNTIFS(WasteLog!$A$2:$A$121,$A7),0) -> 80.92 | E7: =IF(OR($B7<1500, AND($C7<>"",$C7<3.2), IF($B7>0, $D7>0.04*$B7, $D7>0)), "At Risk", "OK") -> At Risk
A8: =A7+1 -> 45843 | B8: =SUMIFS(Orders!$I:$I, Orders!$B:$B, ">="&$A8, Orders!$B:$B, "<"&($A8+1)) -> 626.2479 | C8: =IFERROR(AVERAGEIFS(Feedback!$C:$C, Feedback!$A:$A, $A8),"") -> 4 | D8: =IFERROR(SUMPRODUCT((WasteLog!$A$2:$A$121=$A8)*WasteLog!$C$2:$C$121*IFERROR(VLOOKUP(WasteLog!$B$2:$B$121,Menu!$A:$E,5,FALSE()),0))/COUNTIFS(WasteLog!$A$2:$A$121,$A8),0) -> 25.013333 | E8: =IF(OR($B8<1500, AND($C8<>"",$C8<3.2), IF($B8>0, $D8>0.04*$B8, $D8>0)), "At Risk", "OK") -> At Risk
A9: =A8+1 -> 45844 | B9: =SUMIFS(Orders!$I:$I, Orders!$B:$B, ">="&$A9, Orders!$B:$B, "<"&($A9+1)) -> 2758.1276 | C9: =IFERROR(AVERAGEIFS(Feedback!$C:$C, Feedback!$A:$A, $A9),"") -> 3.5 | D9: =IFERROR(SUMPRODUCT((WasteLog!$A$2:$A$121=$A9)*WasteLog!$C$2:$C$121*IFERROR(VLOOKUP(WasteLog!$B$2:$B$121,Menu!$A:$E,5,FALSE()),0))/COUNTIFS(WasteLog!$A$2:$A$121,$A9),0) -> 148.14 | E9: =IF(OR($B9<1500, AND($C9<>"",$C9<3.2), IF($B9>0, $D9>0.04*$B9, $D9>0)), "At Risk", "OK") -> At Risk
A10: =A9+1 -> 45845 | B10: =SUMIFS(Orders!$I:$I, Orders!$B:$B, ">="&$A10, Orders!$B:$B, "<"&($A10+1)) -> 1619.6286 | C10: =IFERROR(AVERAGEIFS(Feedback!$C:$C, Feedback!$A:$A, $A10),"") -> 4.75 | D10: =IFERROR(SUMPRODUCT((WasteLog!$A$2:$A$121=$A10)*WasteLog!$C$2:$C$121*IFERROR(VLOOKUP(WasteLog!$B$2:$B$121,Menu!$A:$E,5,FALSE()),0))/COUNTIFS(WasteLog!$A$2:$A$121,$A10),0) -> 21.95 | E10: =IF(OR($B10<1500, AND($C10<>"",$C10<3.2), IF($B10>0, $D10>0.04*$B10, $D10>0)), "At Risk", "OK") -> OK
A11: =A10+1 -> 45846 | B11: =SUMIFS(Orders!$I:$I, Orders!$B:$B, ">="&$A11, Orders!$B:$B, "<"&($A11+1)) -> 425.1991 | C11: =IFERROR(AVERAGEIFS(Feedback!$C:$C, Feedback!$A:$A, $A11),"") -> 4 | D11: =IFERROR(SUMPRODUCT((WasteLog!$A$2:$A$121=$A11)*WasteLog!$C$2:$C$121*IFERROR(VLOOKUP(WasteLog!$B$2:$B$121,Menu!$A:$E,5,FALSE()),0))/COUNTIFS(WasteLog!$A$2:$A$121,$A11),0) -> 85.6975 | E11: =IF(OR($B11<1500, AND($C11<>"",$C11<3.2), IF($B11>0, $D11>0.04*$B11, $D11>0)), "At Risk", "OK") -> At Risk
A12: =A11+1 -> 45847 | B12: =SUMIFS(Orders!$I:$I, Orders!$B:$B, ">="&$A12, Orders!$B:$B, "<"&($A12+1)) -> 2706.5737 | C12: =IFERROR(AVERAGEIFS(Feedback!$C:$C, Feedback!$A:$A, $A12),"") -> 3.1666667 | D12: =IFERROR(SUMPRODUCT((WasteLog!$A$2:$A$121=$A12)*WasteLog!$C$2:$C$121*IFERROR(VLOOKUP(WasteLog!$B$2:$B$121,Menu!$A:$E,5,FALSE()),0))/COUNTIFS(WasteLog!$A$2:$A$121,$A12),0) -> 18.906667 | E12: =IF(OR($B12<1500, AND($C12<>"",$C12<3.2), IF($B12>0, $D12>0.04*$B12, $D12>0)), "At Risk", "OK") -> At Risk
A13: =A12+1 -> 45848 | B13: =SUMIFS(Orders!$I:$I, Orders!$B:$B, ">="&$A13, Orders!$B:$B, "<"&($A13+1)) -> 3654.4446 | C13: =IFERROR(AVERAGEIFS(Feedback!$C:$C, Feedback!$A:$A, $A13),"") -> 4 | D13: =IFERROR(SUMPRODUCT((WasteLog!$A$2:$A$121=$A13)*WasteLog!$C$2:$C$121*IFERROR(VLOOKUP(WasteLog!$B$2:$B$121,Menu!$A:$E,5,FALSE()),0))/COUNTIFS(WasteLog!$A$2:$A$121,$A13),0) -> 35.81 | E13: =IF(OR($B13<1500, AND($C13<>"",$C13<3.2), IF($B13>0, $D13>0.04*$B13, $D13>0)), "At Risk", "OK") -> OK
A14: =A13+1 -> 45849 | B14: =SUMIFS(Orders!$I:$I, Orders!$B:$B, ">="&$A14, Orders!$B:$B, "<"&($A14+1)) -> 3744.4975 | C14: =IFERROR(AVERAGEIFS(Feedback!$C:$C, Feedback!$A:$A, $A14),"") -> 3.5 | D14: =IFERROR(SUMPRODUCT((WasteLog!$A$2:$A$121=$A14)*WasteLog!$C$2:$C$121*IFERROR(VLOOKUP(WasteLog!$B$2:$B$121,Menu!$A:$E,5,FALSE()),0))/COUNTIFS(WasteLog!$A$2:$A$121,$A14),0) -> 43.9 | E14: =IF(OR($B14<1500, AND($C14<>"",$C14<3.2), IF($B14>0, $D14>0.04*$B14, $D14>0)), "At Risk", "OK") -> OK
